Workbook
Name BasicPrice: 假设及结论!$P$15
Name CapitalRatio: 假设及结论!$Q$30
Name CirculatingFund: 假设及结论!$B$33
Name circulatingRate: 假设及结论!$N$30
Name CirculatingRatio: 假设及结论!$N$30
Name ConstructPeriod: 假设及结论!$G$13
Name CPI: 假设及结论!$K$33
Name DebtPeriod: 假设及结论!$O$30
Name DebtRate: 假设及结论!$P$30
Name DebtRatio: 1-假设及结论!$Q$30
Name DeprecitionPeriod: 假设及结论!$G$33
Name DiscountRate: WACC!$C$19
Name FixedAssets: 假设及结论!$C$33
Name OperationPeriod: 假设及结论!$H$13
Name SubsidyLossMonths: "="
Name type: 假设及结论!$D$13
Name WACC: WACC!$C$19
Name InstalledCapacity: 假设及结论!$F$13
Name TotalInvestment: 假设及结论!$B$13

Sheet 储能投资明细
B3: 100M/200MWh獨立儲能電站的投資構成明細 | E3: 汇率 | F3: 7.02
B4: 明细 | C4: 单价 | D4: 单位 | E4: 数量 | F4: 小计
B5: 硬體成本 | F5: =SUM(F7:F21) -> 34880000 | G5: =F5*$F$3 -> 244857600
B6: 儲能設備（BatteryEnergyStorageSystem,BESS）
B7: 電池儲能系統（Battery） | C7: 1800 | D7: 美元/个 | E7: 13500 | F7: =C7*E7 -> 24300000 | G7: =F7*$F$3 -> 170586000
B8: 變壓器（Transformer） | C8: 70000 | D8: 美元/个 | E8: 3 | F8: =C8*E8 -> 210000 | G8: =F8*$F$3 -> 1474200
B9: 逆變器（Inverter） | C9: 40000 | D9: 美元/个 | E9: 15 | F9: =C9*E9 -> 600000 | G9: =F9*$F$3 -> 4212000
B10: 控制系統（ControlSystem） | C10: 70000 | D10: 套 | E10: 1 | F10: =C10*E10 -> 70000 | G10: =F10*$F$3 -> 491400
B11: 電力轉換設備 | F11: =C11*E11 -> 0
B12: 變壓器（Transformer） | C12: 800000 | D12: 美元/个 | E12: 2 | F12: =C12*E12 -> 1600000 | G12: =F12*$F$3 -> 11232000
B13: 逆變器（Inverter） | C13: 500000 | D13: 美元/个 | E13: 10 | F13: =C13*E13 -> 5000000 | G13: =F13*$F$3 -> 35100000
B14: 配電設備（Distribution equipment） | C14: 500000 | D14: 批 | E14: 1 | F14: =C14*E14 -> 500000
B15: 監控系統 | F15: =C15*E15 -> 0
B16: 感測器（Sensor） | C16: 200000 | D16: 批 | E16: 1 | F16: =C16*E16 -> 200000 | G16: =F16*$F$3 -> 1404000
B17: 基礎設施 | F17: =C17*E17 -> 0
B18: 土地購置或租賃 | C18: 5000 | D18: 美元/亩 | E18: 100 | F18: =C18*E18 -> 500000 | G18: =F18*$F$3 -> 3510000
B19: 建築物（如控制室、維護室） | C19: 600 | D19: 美元/平米 | E19: 1500 | F19: =C19*E19 -> 900000
B20: 冷卻系統 | C20: 800000 | D20: 項 | E20: 1 | F20: =C20*E20 -> 800000
B21: 消防係統 | C21: 200000 | D21: 項 | E21: 1 | F21: =C21*E21 -> 200000 | G21: =F19*$F$3 -> 6318000
B22: 軟體成本 | F22: =SUM(F24:F27) -> 1310000 | G22: =F22*$F$3 -> 9196200
B23: 控制系統軟體 | F23: =C23*E23 -> 0
B24: 儲能控制系統（EnergyStorageManagementSystem） | C24: 1000000 | D24: 套 | E24: 1 | F24: =C24*E24 -> 1000000 | G24: =F24*$F$3 -> 7020000
B25: 監控軟體 | F25: =C25*E25 -> 0
B26: SCADA系統 | C26: 300000 | D26: 套 | E26: 1 | F26: =C26*E26 -> 300000 | G26: =F26*$F$3 -> 2106000
B27: 數據分析軟體（DataAnalytics） | C27: 10000 | D27: 套 | E27: 1 | F27: =C27*E27 -> 10000 | G27: =F27*$F$3 -> 70200
B28: 工程成本 | F28: =SUM(F29:F36) -> 6310000 | G28: =F28*$F$3 -> 44296200
B29: 設計與規劃 | F29: =C29*E29 -> 0
B30: 工程師費用（EngineeringFee） | C30: 120000 | D30: 项 | E30: 1 | F30: =C30*E30 -> 120000 | G30: =F30*$F$3 -> 842400
B31: 設計軟體費用（DesignSoftwareFee） | C31: 120000 | D31: 项 | E31: 1 | F31: =C31*E31 -> 120000 | G31: =F31*$F$3 -> 842400
B32: 建築安裝 | F32: =C32*E32 -> 0
B33: 施工費用（ConstructionFee） | C33: 6000000 | D33: 项 | E33: 1 | F33: =C33*E33 -> 6000000 | G33: =F33*$F$3 -> 42120000
B34: 測試與驗證 | F34: =C34*E34 -> 0
B35: 測試設備費用（TestingEquipmentFee） | C35: 35000 | D35: 项 | E35: 1 | F35: =C35*E35 -> 35000 | G35: =F35*$F$3 -> 245700
B36: 測試人員費用（TestingPersonnelFee） | C36: 35000 | D36: 项 | E36: 1 | F36: =C36*E36 -> 35000 | G36: =F36*$F$3 -> 245700
B37: 工程成本總計
B38: 營運成本 | F38: =SUM(F39:F47) -> 760000 | G38: =F38*$F$3 -> 5335200
B39: 維護費用 | F39: =C39*E39 -> 0
B40: 定期維護費用（RegularMaintenanceFee） | C40: 120000 | D40: 项 | E40: 1 | F40: =C40*E40 -> 120000 | G40: =F40*$F$3 -> 842400
B41: 非預期維護費用（UnplannedMaintenanceFee） | C41: 30000 | D41: 项 | E41: 1 | F41: =C41*E41 -> 30000 | G41: =F41*$F$3 -> 210600
B42: 人工成本 | F42: =C42*E42 -> 0
...

Sheet Sheet2
B3: 手续清单
B4: 序号 | C4: 许可文件 | D4: 主管部门 | E4: 备注
B5: 1 | C5: 公司注册 | D5: 乌兹别克斯坦共和国司法部国家服务局 | E5: 业主需求，需当地缴纳税费，开具增值税法发票
B6: 2 | C6: 税务登记 | D6: 国家税务委员会税务检查机关
B7: 3 | C7: 临时土地使用权证（如适用） | D7: 乌兹别克斯坦共和国国土资源、大地测量、制图和地籍委员会 | E7: 不需要。
B8: 4 | C8: 建筑规划任务书（如适用） | D8: 乌兹别克斯坦共和国建设部 | E8: 不需要，由业主办理完国家能源部项目批复及内务府开具的总统令即可
B9: 5 | C9: 项目施工许可证（如适用） | D9: 乌兹别克斯坦共和国建设部 | E9: 不需要，由业主办理完国家能源部项目批复及内务府开具的总统令即可
B10: 6 | C10: 环境影响评估报告 | D10: 乌兹别克斯坦共和国环境专业技术中心 | E10: 需要，可以委托纳曼干项目塔什干ABREST公司办理
B11: 7 | C11: 危险生产设施工及运营项目许可证 | D11: 乌兹别克斯坦共和国建设部 | E11: 不需要
B12: 8 | C12: 无人驾驶民用航空器（无人机）使用许可证（如适用） | D12: 乌兹别克斯坦共和国国家飞行安全监察局 | E12: 不需要
B13: 9 | C13: 项目文档许可(PD)（如适用） | D13: 乌兹别克斯坦共和国建设部城市（地区）建设局建筑委员会 | E13: 不需要
B14: 10 | C14: 工业安全规范符合确认书（如适用） | D14: 认证机构 | E14: 不需要
B15: 11 | C15: 危险设备安装和使用许可证（如适用） | D15: 乌兹别克斯坦共和国国家工业安全委员会 | E15: 不需要
B16: 12 | C16: 国家项目验收（如适用） | D16: 乌兹别克斯坦共和国建设部 | E16: 需要，可以委托纳曼干项目塔什干ABREST公司办理
B17: 13 | C17: 并网、消纳报告批复 | D17: 国家电网NEGU | E17: 只需要电网批复报告即可，可以委托纳曼干项目塔什干ABREST公司办理
B18: 14 | C18: 外国分包、当地分包单位各等级（类别）电力、工程施工资质 | D18: 国家电网、建设部 | E18: 调试，安装，土建等分包需要资质，我司合作的分包具备以上条件
... B29: 26 | C29: EIF、开关站征地令 | D29: 纳沃依州纳沃依市市政府、区政府 | E29: 需要，由核工业金华勘测设计有限公司将测绘坐标及线路批复上报至纳沃伊市 KARMANI 区政府进行申请，7个工作日公示完成，完成后进行土地租赁
B30: 27 | C30: EIF、开关站征地补偿以及缴费证明
B31: 28 | C31: 乌兹别克斯坦共和国建设部颁发的高空作业和维修的许可证 | D31: 建设部 | E31: 不需要
B32: 29 | C32: 乌兹别克斯坦共和国国家地质和矿产资源委员会下属的水文地质组织颁布水文结论。 | D32: 国家地质矿产委员会 | E32: 不需要
B33: 30 | C33: 特殊用水许可证（如适用） | D33: 乌兹别克斯坦共和国国家生态与环境保护委员会（天然水源区取水）、乌兹别克斯坦共和国国家地质与矿产资源委员会（地下水源区取水）及乌兹别克斯坦共和国水资源管理部（人工储水区取水）各地区部门（不用打井，不用办） | E33: 我司在当地已有打井合作公司，可以办理相关许可
B34: 31 | C34: 与当地天然气供应公司签署合同并获取天然气技术接入条件、使用许可 | D34: 乌兹天然气输送公司 | E34: 不需要
B35: 32 | C35: 与当地电力供应商签订合同并获取技术条件 | D35: 地区电网局 | E35: 不需要
B36: 33 | C36: 对外贷款协议登记（如适用） | D36: 乌兹别克斯坦共和国中央银行 | E36: 本地服务银行通知，不需要
B37: 34 | C37: 取得特定货物进出口许可证 | D37: 乌兹别克斯坦共和国内阁对外贸易发展、产业、地区出口潜力信息与分析部 | E37: 不需要
B38: 35 | C38: 乌兹别克斯坦进口设备免征关税与增值税（免税清单） | D38: 国家税务委员会税务检查机关 | E38: 需要，需咨询海关免税政策，免税清单。
B39: 36 | C39: 进口货物证明书 | D39: 乌兹别克斯坦标准认证中心 | E39: 需要，或授权认证机构，厂家出货时提供
B40: 37 | C40: 外籍工人工作签证与就业许可证 | D40: 外籍劳工移民局 | E40: 签证要商务签，当地公司成立后与公司签订劳务合同，建议和劳务公司签订，手续费用低。
B41: 38 | C41: 与当地法规相关的其他文件 | D41: 乌兹别克斯坦国家电网股份公司等 | E41: 需要，可委托纳曼甘项目现合作的JURU设计院上报电网
B42: 39 | C42: 项目建筑物不动产权登记证（项目建成后） | D42: 州地籍委员会 | E42: 业主来办
... B45: 42 | C45: 发电许可证 | D45: 乌兹别克斯坦国家电网股份公司 | E45: 只要并网许可证，塔什干ABREST公司可以办理
B46: 43 | C46: 其他 | D46: 与本项目投资、建设与运营相关，包含但不限于上述范围的其他许可及政府批准。

Sheet 11院概算
B3: 序号 | C3: 工程和费用名称 | D3: 费率 | E3: 建筑工程 | F3: 设备购置费 | G3: 安装工程费 | H3: 其他费用 | I3: 总值 | J3: 占固定资产投资（%）
E5: a | F5: b | G5: c
B6: 1 | C6: 工程费用 | E6: =E7+E11 -> 122140 | F6: =F7+F11 -> 76042 | G6: =G7+G11 -> 55160 | H6: =H7+H11 -> 0 | I6: =I7+I11 -> 253342 | J6: =I6/$I$31 -> 0.89317691
B7: 1.1 | C7: 设备费 | E7: =SUM(E8:E10) -> 0 | F7: =SUM(F8:F10) -> 76042 | G7: =SUM(G8:G10) -> 55160 | H7: =SUM(H8:H10) -> 0 | I7: =SUM(I8:I10) -> 131202
B8: 1.1.1 | C8: 光伏设备及安装工程 | F8: 76042 | G8: 39400 | I8: =SUM(E8:H8) -> 115442
B9: 1.1.2 | C9: 电缆线路及安装工程 | G9: 11820 | I9: =SUM(E9:H9) -> 11820
B10: 1.1.3 | C10: 其他设备及安装工程 | G10: 3940 | I10: =SUM(E10:H10) -> 3940
B11: 1.2 | C11: 建筑工程 | E11: =E12 -> 122140 | F11: =F12 -> 0 | G11: =G12 -> 0 | H11: =H12 -> 0 | I11: =I12 -> 122140
B12: 1.2.1 | C12: 发电场基础工程 | E12: 122140 | I12: =SUM(E12:H12) -> 122140
B13: 2 | C13: 工程建设其他费用 | E13: =E14+E15+E25+E26 -> 0 | F13: =F14+F15+F25+F26 -> 0 | G13: =G14+G15+G25+G26 -> 0 | H13: =H14+H15+H25+H26 -> 11783.475 | I13: =I14+I15+I25+I26 -> 11783.475 | J13: =I13/$I$31 -> 0.041543556
B14: 2.1 | C14: 项目建设用地费 | H14: 50 | I14: =SUM(E14:H14) -> 50
B15: 2.2 | C15: 项目建设管理费 | E15: =SUM(E16:E24) -> 0 | F15: =SUM(F16:F24) -> 0 | G15: =SUM(G16:G24) -> 0 | H15: =SUM(H16:H24) -> 9372.1146 | I15: =SUM(I16:I24) -> 9372.1146
B16: 2.2.1 | C16: 工程前期费 | H16: 2658 | I16: =SUM(E16:H16) -> 2658
B17: 2.2.2 | C17: 工程建设管理费（Based：a+b+c) | D17: 0.0117 | H17: =($E$6+$F$6+$G$6)*D17 -> 2964.1014 | I17: =SUM(E17:H17) -> 2964.1014
B18: 2.2.3 | C18: 工程建设监理费（Based：a+b+c) | D18: 0.0043 | H18: =($E$6+$F$6+$G$6)*D18 -> 1089.3706 | I18: =SUM(E18:H18) -> 1089.3706
B19: 2.2.4 | C19: 咨询服务费（Based：a+b+c) | D19: 0.0026 | H19: =($E$6+$F$6+$G$6)*D19 -> 658.6892 | I19: =SUM(E19:H19) -> 658.6892
B20: 2.2.5 | C20: 项目技术经济评审费（Based：a+b+c) | D20: 0.0015 | H20: =($E$6+$F$6+$G$6)*D20 -> 380.013 | I20: =SUM(E20:H20) -> 380.013
B21: 2.2.6 | C21: 工程质量检查检测费（Based：a+c) | D21: 0.0011 | H21: =($E$6+$G$6)*D21 -> 195.03 | I21: =SUM(E21:H21) -> 195.03
B22: 2.2.7 | C22: 项目验收费（Based：a+b+c) | D22: 0.0034 | H22: =($E$6+$F$6+$G$6)*D22 -> 861.3628 | I22: =SUM(E22:H22) -> 861.3628
B23: 2.2.8 | C23: 工程保险费（Based：a+b+c) | D23: 0.0021 | H23: =($E$6+$F$6+$G$6)*D23 -> 532.0182 | I23: =SUM(E23:H23) -> 532.0182
B24: 2.2.9 | C24: 土地补偿款 | H24: =假设及结论!K21 -> 33.52944 | I24: =SUM(E24:H24) -> 33.52944
B25: 2.3 | C25: 生产准备费（Based：b) | D25: 0.0054 | H25: =($F$6)*D25 -> 410.6268 | I25: =SUM(E25:H25) -> 410.6268
B26: 2.4 | C26: 勘察费设计费（Based：a+b+c) | D26: 0.0077 | H26: =($E$6+$F$6+$G$6)*D26 -> 1950.7334 | I26: =SUM(E26:H26) -> 1950.7334
B27: 3 | C27: 预备费 | H27: =H28 -> 15200.52 | I27: =I28 -> 15200.52 | J27: =I27/$I$31 -> 0.053590615
B28: 3.1 | C28: 基本预备费（Based：a+b+c) | D28: 0.06 | H28: =($E$6+$F$6+$G$6)*D28 -> 15200.52 | I28: =SUM(E28:H28) -> 15200.52
B29: 4 | C29: 建设投资合计 | E29: =E6+E13+E27 -> 122140 | F29: =F6+F13+F27 -> 76042 | G29: =G6+G13+G27 -> 55160 | H29: =H6+H13+H27 -> 26983.995 | I29: =I6+I13+I27 -> 280325.99
B30: 5 | C30: 建设期利息 | H30: =假设及结论!L7 -> 3315.4619 | I30: =SUM(E30:H30) -> 3315.4619 | J30: =I30/$I$31 -> 0.011688919
B31: 6 | C31: 固定资产投资合计 | E31: =E29+E30 -> 122140 | F31: =F29+F30 -> 76042 | G31: =G29+G30 -> 55160 | H31: =H29+H30 -> 30299.457 | I31: =I29+I30 -> 283641.46 | J31: =I31/$I$31 -> 1
C32: 单位千瓦的静态投资（元/千瓦） | I32: =I29/假设及结论!$F$13 -> 3737.6799
C33: 单位千瓦的动态投资（元/千瓦） | I33: =I31/假设及结论!$F$13 -> 3781.8861
B34: 7 | C34: 流动资金 | H34: =假设及结论!B33 -> 1500 | I34: =SUM(E34:H34) -> 1500
B35: 8 | C35: 总投资合计 | E35: =E31+E34 -> 122140 | F35: =F31+F34 -> 76042 | G35: =G31+G34 -> 55160 | H35: =H31+H34 -> 31799.457 | I35: =I31+I34 -> 285141.46
C36: 比例(%) | E36: =E35/$I$35 -> 0.4283488 | F36: =F35/$I$35 -> 0.26668167 | G36: =G35/$I$35 -> 0.19344784 | H36: =H35/$I$35 -> 0.11152169 | I36: =SUM(E36:H36) -> 1

Sheet Sheet1
B2: 光伏设备购置费明细
B3: 序号 | C3: 设备名称 | D3: 数量/规格 | E3: 单价（元/单位） | F3: 总价（元） | G3: 备注
B4: 1 | C4: 光伏组件 | D4: ="光伏组件（共 "&TEXT(ROUNDUP(假设及结论!F13*10^7/MID(G4,7,3),0),"###,#0")&" 块）" -> 光伏组件（共 1,041,667 块） | E4: 576 | F4: =INT(MID(D4,7,11))*E4 -> 600000192 | G4: 单块组件功率720W
B5: 2 | C5: 逆变器 | D5: 100 台（8MW） | E5: 1000000 | F5: 100000000 | G5: 单台逆变器容量8MW
B6: 3 | C6: 汇流箱 | D6: 400 个（2MW） | E6: 200000 | F6: 80000000 | G6: 单个汇流箱容量2MW
B7: 4 | C7: 支架 | D7: 1083334 | E7: 143 | F7: =D7*E7 -> 154916762 | G7: 包括地梁、立柱、横梁等
B8: 5 | C8: 监控系统 | D8: 10 | E8: 100000 | F8: =D8*E8 -> 1000000 | G8: 包括摄像头、数据采集器等
B9: 6 | C9: 避雷系统 | D9: 400 | E9: 5000 | F9: =D9*E9 -> 2000000 | G9: 包括避雷针、避雷带等
B10: 7 | C10: 并网设备 | D10: 1 | E10: 500000 | F10: 500000 | G10: 包括并网箱、断路器等
B11: 8 | C11: 电缆 | D11: 500000 | E11: 100 | F11: 50000000 | G11: 包括直埋电缆、桥架电缆等
B12: 合计 | C12: - | D12: - | E12: - | F12: =SUM(F4:F11) -> 988416954 | G12: -
B14: 500kV升压站设备购置费明细
B15: 序号 | C15: 设备名称 | D15: 数量/规格 | E15: 单价（元/单位） | F15: 总价（元） | G15: 备注
B16: 1 | C16: 主变压器（500kV） | D16: 2台 | E16: 15,000,000.00 元/台 | F16: 30000000 | G16: 500kV主变压器
B17: 2 | C17: 高压断路器 | D17: 4台 | E17: 1,500,000.00 元/台 | F17: 6000000 | G17: 500kV高压断路器
B18: 3 | C18: 隔离开关 | D18: 8台 | E18: 500,000.00 元/台 | F18: 4000000 | G18: 500kV隔离开关
B19: 4 | C19: 避雷器 | D19: 10个 | E19: 200,000.00 元/个 | F19: 2000000 | G19: 500kV避雷器
B20: 5 | C20: 互感器 | D20: 10个 | E20: 300,000.00 元/个 | F20: 3000000 | G20: 500kV电流/电压互感器
B21: 6 | C21: 保护装置 | D21: 1套 | E21: 2,000,000.00 元/套 | F21: 2000000 | G21: 500kV保护装置
B22: 7 | C22: 控制系统 | D22: 1套 | E22: 1,500,000.00 元/套 | F22: 1500000 | G22: 500kV控制系统
B23: 8 | C23: 监控系统 | D23: 1套 | E23: 1,000,000.00 元/套 | F23: 1000000 | G23: 500kV监控系统
B24: 9 | C24: 消防系统 | D24: 1套 | E24: 500,000.00 元/套 | F24: 500000 | G24: 500kV消防系统
B25: 10 | C25: 通信系统 | D25: 1套 | E25: 800,000.00 元/套 | F25: 800000 | G25: 500kV通信系统
B26: 合计 | C26: - | D26: - | E26: - | F26: =SUM(F16:F25) -> 50800000 | G26: -
B29: 土建工程概算明细
B30: 序号 | C30: 工程内容 | D30: 数量/规格 | E30: 单价（元/单位） | F30: 总价（元） | G30: 备注
B31: 1 | C31: 场地平整 | D31: 12,327,000 m² | E31: 15.00 元/m² | F31: 184905000 | G31: 包括清理杂物、平整土地等
B32: 2 | C32: 基础工程 | D32: 1,083,334 个桩基础 | E32: 800.00 元/个 | F32: 866667200 | G32: 包括混凝土、钢筋等材料
B33: 3 | C33: 道路硬化 | D33: 500,000 m² | E33: 120.00 元/m² | F33: 60000000 | G33: 包括场内道路、硬化面积等
B34: 4 | C34: 围栏工程 | D34: 50,000 m | E34: 150.00 元/m | F34: 7500000 | G34: 包括围栏材料、安装费用等
B35: 5 | C35: 排水系统 | D35: 10,000 m 排水沟 | E35: 200.00 元/m | F35: 2000000 | G35: 包括排水管道、雨水收集系统等
B36: 6 | C36: 监控室建设 | D36: 1 间（50 m²） | E36: 3,000.00 元/间 | F36: 3000 | G36: 包括建筑、防水处理等
B37: 7 | C37: 500kV升压站建设 | D37: 1 座 | E37: 50,000,000.00 元/座 | F37: =F26 -> 50800000 | G37: 包括升压站房屋、设备安装等
B38: 8 | C38: 接入线路建设 | D38: 8公里 | E38: 10,000,000.00 元/公里 | F38: 80000000 | G38: 包括线路杆塔、电缆敷设等
B39: 9 | C39: 其他辅助设施 | D39: - | E39: - | F39: 50000 | G39: 包括消防设施、照明系统等
B40: 合计 | C40: - | D40: - | E40: - | F40: =SUM(F31:F39) -> 1251925200 | G40: -
B43: 3. 安装工程概算明细
B44: 序号 | C44: 工程内容 | D44: 数量/规格 | E44: 单价（元/单位） | F44: 总价（元） | G44: 备注
B45: 1 | C45: 光伏组件安装 | D45: 1,083,334 块组件 | E45: 300.00 元/块 | F45: 325000200 | G45: 包括组件固定、接线盒安装等
B46: 2 | C46: 支架安装 | D46: 1,083,334 套支架 | E46: 1,500.00 元/套 | F46: 1625001100 | G46: 包括地梁、立柱、横梁等
...

Sheet 投资构成
C4: 此色块为参数设定 | D4: 吉尔吉斯斯坦780MW/600MW光伏电站投资构成（含500kv变电站） | J4: 运费(1500公里，4300元/吨) | L4: 准备 | M4: 空间
C5: 项目类别 | D5: 项目名称 | E5: 单位 | F5: 数量 | G5: 单价（元） | H5: 总价（万元） | I5: 备注 | J5: 重量(吨) | K5: 运费 | M5: 单价上浮 | N5: 金额(万)
M6: 当地成立公司采购
C7: 发电设备 | D7: ="光伏组件（共 "&TEXT(ROUNDUP($F$7/MID($I$7,7,3),0),"###,#0")&" 块）" -> 光伏组件（共 1,083,334 块） | E7: W | F7: 780000000 | G7: 0.75 | H7: =F7*G7/10000 -> 58500 | I7: 单块组件功率720W | J7: 500 | K7: =MID($J$4,11,4)*J7*$F$7/1000000/10/10000 -> 16770 | L7: 2024市场价 | M7: 0.08 | N7: =M7*F7/10000 -> 6240
D8: 逆变器(共台) | E8: W | F8: 780000000 | G8: 0.13 | H8: =F8*G8/10000 -> 10140 | I8: 单台8.8MW和6.6MW | J8: 25 | K8: =MID($J$4,11,3)*J8*$F$7/1000000/10/10000 -> 83.85 | L8: 2024市场价 | M8: 0.02 | N8: =M8*F8/10000 -> 1560
D9: 支架系统 | E9: W | F9: 780000000 | G9: 0.24 | H9: =F9*G9/10000 -> 18720 | J9: 400 | K9: =MID($J$4,11,3)*J9*$F$7/1000000/10/10000 -> 1341.6 | L9: 2024市场价 | M9: 0.03 | N9: =M9*F9/10000 -> 2340 | P9: =156000000/1083334 -> 143.99991
D10: 汇流箱 | E10: 台 | F10: 7800 | G10: 3000 | H10: =F10*G10/10000 -> 2340 | J10: 4 | K10: =MID($J$4,11,3)*J10*$F$7/1000000/10/10000 -> 13.416 | L10: 2024电网参考价 | M10: 500 | N10: =M10*F10/10000 -> 390
D11: 变压器 | E11: 台 | F11: 78 | G11: 580000 | H11: =F11*G11/10000 -> 4524 | J11: 32 | K11: =MID($J$4,11,3)*J11*$F$7/1000000/10/10000 -> 107.328 | L11: 2024电网参考价 | M11: 40000 | N11: =M11*F11/10000 -> 312
D12: 配电柜及配电装置 | E12: 台 | F12: 78 | G12: 100000 | H12: =F12*G12/10000 -> 780 | J12: 10 | K12: =MID($J$4,11,3)*J12*$F$7/1000000/10/10000 -> 33.54 | L12: 2024电网参考价 | M12: 20000 | N12: =M12*F12/10000 -> 156
D13: 通讯及监控系统 | E13: 套 | F13: 30 | G13: 287000 | H13: =F13*G13/10000 -> 861 | J13: 2 | K13: =MID($J$4,11,3)*J13*$F$7/1000000/10/10000 -> 6.708 | L13: 2024电网参考价 | M13: 150000 | N13: =M13*F13/10000 -> 450
D14: 避雷系统 | E14: 套 | F14: 10 | G14: 287000 | H14: =F14*G14/10000 -> 287 | J14: 2 | K14: =MID($J$4,11,3)*J14*$F$7/1000000/10/10000 -> 6.708
D15: 电缆及附件 | E15: km | F15: 500 | G15: 358000 | H15: =F15*G15/10000 -> 17900 | J15: 55 | K15: =MID($J$4,11,3)*J15*$F$7/1000000/10/10000 -> 184.47 | M15: 10000 | N15: =M15*F15/10000 -> 500
D16: 发电设备小计 | E16: 万元 | H16: =SUM(H7:H15) -> 114052 | K16: =SUM(K7:K15) -> 18547.62 | M16: 合计 | N16: =SUM(N7:N15) -> 11948
C18: 发电场工程 | D18: 土建工程 | E18: W | F18: 780000000 | G18: 0.1 | H18: =F18*G18/10000 -> 7800 | L18: 单价暂定 | M18: 0.03 | N18: =M18*F18/10000 -> 2340
D19: 安装工程 | E19: W | F19: 780000000 | G19: =H19*10000/F19 -> 0.23833335 | H19: =H20+H21+H23 -> 18590.001 | M19: 0.03 | N19: =M19*F19/10000 -> 2340
D20: 组件安装 | E20: 块 | F20: =TEXT(ROUNDUP($F$7*10/MID($I$7,7,3),0),"###,#0") -> 10,833,334 | G20: 15 | H20: =F20*G20/10000 -> 16250.001 | L20: 单价暂定 | M20: 10 | N20: =F20*M20/10000 -> 10833.334
D21: 电气安装 | E21: MW | F21: =F7/1000000 -> 780 | G21: 18000 | H21: =F21*G21/10000 -> 1404 | L21: 单价暂定 | M21: 3000 | N21: =F21*M21/10000 -> 234
D22: 支架安装 | E22: 套 | F22: =TEXT(ROUNDUP($F$7*10/MID($I$7,7,3),0),"###,#0") -> 10,833,334 | G22: 15 | H22: =F22*G22/10000 -> 16250.001
D23: 调试和测试 | E23: MW | F23: =F7/1000000 -> 780 | G23: 12000 | H23: =F23*G23/10000 -> 936 | L23: 单价暂定 | M23: 3000 | N23: =F23*M23/10000 -> 234
D24: 场地平整 | E24: 亩 | F24: =假设及结论!G21*10000/666 -> 18509.009 | G24: 2000 | H24: =F24*G24/10000 -> 3701.8018 | L24: 单价暂定 | M24: 500 | N24: =M24*F24/10000 -> 925.45045
D25: 道路建设 | E25: km | F25: 120 | G25: 500000 | H25: =F25*G25/10000 -> 6000 | L25: 单价暂定 | M25: 300000 | N25: =F25*M25/10000 -> 3600
D26: 发电场工程小计 | E26: 万元 | H26: =SUM(H18:H25)-SUM(H20:H23) -> 36091.803 | M26: 合计 | N26: =SUM(N18:N25) -> 20506.784
J27: 吨/套（台）
C28: 500kv变电站设备 | D28: 500kV主变压器（1000MVA） | E28: 台 | F28: 2 | G28: 32000000 | H28: =F28*G28/10000 -> 6400 | J28: 300 | K28: =F28*J28*MID($J$4,11,4)/10000 -> 258 | L28: 2024电网参考价
D29: 500kV GIS组合电器 | E29: 套 | F29: 1 | G29: =H29*10000 -> 45000000 | H29: =SUM(H30:H34) -> 4500 | J29: {=SUMPRODUCT(F30:F34*J30:J34)} -> 156 | K29: =F29*J29*MID($J$4,11,4)/10000 -> 67.08 | L29: 2024电网参考价
D30: 500kV 断路器 | E30: 台 | F30: 6 | G30: 4000000 | H30: =F30*G30/10000 -> 2400 | J30: 8 | K30: =F30*J30*MID($J$4,11,4)/10000 -> 20.64 | L30: 2024电网参考价
D31: 500kV 隔离开关 | E31: 组 | F31: 12 | G31: 800000 | H31: =F31*G31/10000 -> 960 | J31: 5 | K31: =F31*J31*MID($J$4,11,4)/10000 -> 25.8 | L31: 2024电网参考价
D32: 500kV 电流互感器 | E32: 组 | F32: 6 | G32: 600000 | H32: =F32*G32/10000 -> 360 | J32: 3 | K32: =F32*J32*MID($J$4,11,4)/10000 -> 7.74 | L32: 2024电网参考价
D33: 500kV 电压互感器 | E33: 组 | F33: 6 | G33: 800000 | H33: =F33*G33/10000 -> 480 | J33: 4 | K33: =F33*J33*MID($J$4,11,4)/10000 -> 10.32 | L33: 2024电网参考价
D34: 500kV 避雷器 | E34: 组 | F34: 6 | G34: 500000 | H34: =F34*G34/10000 -> 300 | J34: 1 | K34: =F34*J34*MID($J$4,11,4)/10000 -> 2.58 | L34: 2024电网参考价
D35: 500kV 母线及支持设备 | E35: 套 | F35: 1 | G35: 5000000 | H35: =F35*G35/10000 -> 500 | J35: 30 | K35: =F35*J35*MID($J$4,11,4)/10000 -> 12.9 | L35: 2024电网参考价
D36: 无功补偿装置（SVC/STATCOM） | E36: 套 | F36: 1 | G36: 30000000 | H36: =F36*G36/10000 -> 3000 | J36: 100 | K36: =F36*J36*MID($J$4,11,4)/10000 -> 43 | L36: 2024电网参考价
D37: 220kV 配电设备（断路器、母线等） | E37: 套 | F37: 1 | G37: 25000000 | H37: =F37*G37/10000 -> 2500 | J37: 25 | K37: =F37*J37*MID($J$4,11,4)/10000 -> 10.75 | L37: 2024电网参考价
D38: 110kV 配电设备（断路器、母线等） | E38: 套 | F38: 1 | G38: 15000000 | H38: =F38*G38/10000 -> 1500 | J38: 15 | K38: =F38*J38*MID($J$4,11,4)/10000 -> 6.45 | L38: 2024电网参考价
D39: 变电站继电保护系统 | E39: 套 | F39: 1 | G39: 200000 | H39: =F39*G39/10000 -> 20 | J39: 8 | K39: =F39*J39*MID($J$4,11,4)/10000 -> 3.44 | L39: 2024电网参考价
D40: 自动化控制系统 | E40: 套 | F40: 1 | G40: 10000000 | H40: =F40*G40/10000 -> 1000 | J40: 5 | K40: =F40*J40*MID($J$4,11,4)/10000 -> 2.15 | L40: 2024电网参考价
D41: 变电站消防系统 | E41: 套 | F41: 1 | G41: 5000000 | H41: =F41*G41/10000 -> 500 | J41: 4 | K41: =F41*J41*MID($J$4,11,4)/10000 -> 1.72 | L41: 2024电网参考价
D42: 站用变压器（35kV/10kV） | E42: 台 | F42: 2 | G42: 2000000 | H42: =F42*G42/10000 -> 400 | J42: 12 | K42: =F42*J42*MID($J$4,11,4)/10000 -> 10.32 | L42: 2024电网参考价
D43: 升压站设备小计 | E43: 万元 | H43: =SUM(H28:H42)-H29 -> 20320 | K43: =SUM(K28:K42)-K29 -> 415.81
C45: 500kv变电站土建工程 | D45: 变电站建筑工程 | E45: 平方米 | F45: 8000 | G45: 7000 | H45: =F45*G45/10000 -> 5600 | L45: 单价暂定 | M45: 2000 | N45: =M45*F45/10000 -> 1600
...

Sheet 600MW管理总包造价
B2: 吉尔吉斯斯坦巴特肯州巴特肯区阿克塔特尔600兆瓦光伏发电项目管理型总承包报价表 The Quotation for EPCM for 600MW Photovoltaic Power Generation Projectin Aktatyr, Batken District, Batken Region the Kyrgyz Republic
B3: 序号 No. | C3: 项目名称 Item Name | D3: 型号规格 Model / Specification | E3: 单位 Unit | F3: 数量 Quantity | G3: 单价 (人民币:元) Unit Price (RMB: yuan) | H3: 合价 (人民币:万元) Combined price (RMB10K Yuan) | I3: 税金 (tax)
B4: 一 I | C4: Akyraan Energy Corporation Limited
B5: 1 | C5: PPA手续办理、电力接入办理 PPA procedure handling, power access handling | D5: 600MW/750MWp | E5: Wp | F5: 750000000 | G5: 0.02 | H5: =F5*G5/10000 -> 1500 | I5: 所有税金(境内境外)、报关费、管理费、利润均包含在单价和合价之内。 Al1 taxes (domestic and overseas), customs clearance fees, management fees, and profits are in the unit price and total price.
B6: 2 | C6: 项目所需征林征地费用(包含临建、管理人员宿舍、料场等项目建设期问所需占用红线外的土地的协调及租赁)，项目红线内的场地清理平整与征林征(草)地，及附着物的清赔。项目红线内障碍物的迁移及赔偿。 The expenses required for forest and land acquisition for the project (including oordination and leasing of land outside the red line required for temporary construction, material storage, and other project construction during the project period),site clearance and leveling within the project red line, forest (grass) landacquisition, and compensation for attachments. Relocation and compensation for obstacles within the project boundary line. | D6: 600MW/750MWp | E6: Wp | F6: 750000000 | G6: 0.1 | H6: =F6*G6/10000 -> 7500
B7: 3 | C7: 施工许可办理 Handling of construction permits | D7: 600MW/750MWp | E7: Wp | F7: 750000000 | G7: 0.005 | H7: =F7*G7/10000 -> 375
B8: 4 | C8: 并网发电手续办理，并网发电通过审批。整个电站所有调试试验费用(同时满足中国及本地验收标准) Handling procedures for grid-connected power generation, and obtaining approval for grid-connected power generation. All commissioning and testing expenses for the entire power station (meeting both Chinese and local acceptance standards) | D8: 600MW/750MWp | E8: Wp | F8: 750000000 | G8: 0.01 | H8: =F8*G8/10000 -> 750
B9: 5 | C9: 项目验收手续办理，消防验收手续办理，综合楼房产证办理 Handling of project acceptance procedures, handling of fire safety acceptance procedures, and handling of property ownership certificate for the complex building | D9: 600MW/750MWp | E9: Wp | F9: 750000000 | G9: 0.005 | H9: =F9*G9/10000 -> 375
B10: 6 | C10: 用工合规性手续办理，无人驾驶民用航空器(无人机)使用许可证 Handling of employment compliance rocedures, and obtaining a usage license for unmanned civil aircraft (drones) | D10: 600MW/750MWp | E10: Wp | F10: 750000000 | G10: 0.005 | H10: =F10*G10/10000 -> 375
B11: 7 | C11: 对端电站的设计及改造 Design and renovation of the opposite-end ower station | D11: 600MW/750MWp | E11: Wp | F11: 750000000 | G11: 0.02 | H11: =F11*G11/10000 -> 1500
B12: 8 | C12: 项目必需的所有道路建设，进场道路于续办理 All necessary road construction for the project,Handling of access road procedures | D12: 600MW/750MWp | E12: Wp | F12: 750000000 | G12: 0.01 | H12: =F12*G12/10000 -> 750
B13: 9 | C13: 项目红线内的水保设施建设 Construction of water and soil conservation facilities within the project boundary | D13: 600MW/750MWp | E13: Wp | F13: 750000000 | G13: 0.01 | H13: =F13*G13/10000 -> 750
B14: 10 | C14: 其他项目所需的所有上述未列明的政府手续办理 Handling all the aforementioned government procedures not listed, which are required for other projects | D14: 600MW/750MWp | E14: Wp | F14: 750000000 | G14: 0.01 | H14: =F14*G14/10000 -> 750
B15: 11 | C15: 交通费等 Transportation fees,etc | F15: 750000000 | G15: 0.005 | H15: =F15*G15/10000 -> 375
B16: 12 | C16: 小计(一) Total (1) | H16: =SUM(H5:H15) -> 15000
B17: 二 II | C17: Kyrgyzstan New Energy Co.ltd
B18: 1 | C18: 项目防洪设施 Flood control facilities withinthe project | D18: 600MW/750MWp | E18: Wp | F18: 750000000 | G18: 0.03 | H18: =F18*G18/10000 -> 2250 | I18: 所有税金(境内境外)、报关费、管理费、利润均包含在单价和合价之内。 Al1 taxes (domestic and overseas), customs clearance fees, management fees, and profits are in the unit price and total price.
B19: 2 | C19: 项目红线范围内(外)的供水设施及6处清洗用水设施 Water supply facilities within (and outside) the project boundary line, as well as six water storage facilities for cleaning purposes | D19: 600MW/750MWp | E19: Wp | F19: 750000000 | G19: 0.02 | H19: =F19*G19/10000 -> 1500
B20: 3 | C20: 光伏场区围栏 Fence of photovoltaic field area | D20: 600MW/750MWp | E20: Wp | F20: 750000000 | G20: 0.02 | H20: =F20*G20/10000 -> 1500
B21: 4 | C21: 光伏支架桩打桩及箱逆变一体机基础打桩 Pile driving for photovoltaic support and foundation piling for box-type inverter ntegrated machine | D21: 600MW/750MWp，抗15级强风，GPS高精度自动定位打桩系统 Anti level 15 strong wind, GPS high-precision automatic positioning pile driving system | E21: Wp | F21: 750000000 | G21: 0.1 | H21: =F21*G21/10000 -> 7500
B22: 5 | C22: 升压站土建工程、装饰装修工程 Civil engineering and decoration works for the booster station | D22: 600MW/750MWp，管理楼、电控 楼及所有设备基础等 Management building, electrical control building, and all equipment foundations, etc | E22: Wp | F22: 750000000 | G22: 0.03 | H22: =F22*G22/10000 -> 2250
B23: 6 | C23: 储能站土建工程、装饰装修工程(包含储能预留区域的场平及砂石覆盖) Civil engineering and decoration works for the energy storage station (including site leveling and sand and gravel covering for the reserved energy storage area) | D23: 180MW/360MWh+180MW/360MWH | E23: Wp | F23: 750000000 | G23: 0.02 | H23: =F23*G23/10000 -> 1500
B24: 7 | C24: 消防水池、隔油池工程 Fire pool and oil separator project | D24: 600MW/750MWp，360MW/360MWH | E24: Wp | F24: 750000000 | G24: 0.01 | H24: =F24*G24/10000 -> 750
B25: 8 | C25: 升压站、储能站外围工程 Peripheral works of booster station and energy storage station | D25: 600MW/750MWp，360MW/360MWH ，场平、道路、围墙、大门等 Field leveling, roads, walls, gates, etc | E25: Wp | F25: 750000000 | G25: 0.01 | H25: =F25*G25/10000 -> 750
B26: 9 | C26: 外线塔基工程(含征地) External line tower foundation project (including land acquisition) | D26: 600MW/750MWp | E26: Wp | F26: 750000000 | G26: 0.02 | H26: =F26*G26/10000 -> 1500
B27: 10 | C27: 运维车辆、施工辅助机械、备品备件 Operation and maintenance vehicles, construction auxiliary machinery, spare parts | D27: 600MW/750MWp | E27: Wp | F27: 750000000 | G27: 0.02 | H27: =F27*G27/10000 -> 1500
B28: 11 | C28: 临水临电、临建、管理人员宿舍、办公网络工程 Temporary water and electricity supply, temporary construction, and office network engineering | D28: 600MW/750MWp | E28: Wp | F28: 750000000 | G28: 0.01 | H28: =F28*G28/10000 -> 750
B29: 12 | C29: 35KV首批并网发电接入工程 The first batch of 35KV grid-connected power generation access project | D29: 600MW/750MWp | E29: Wp | F29: 750000000 | G29: 0.03 | H29: =F29*G29/10000 -> 2250
B30: 13 | C30: 1MWp样板区建设 Construction of 1MWp demonstration area | D30: 600MW/750MWp | E30: Wp | F30: 750000000 | G30: 0.005 | H30: =F30*G30/10000 -> 375
... B33: 16 | C33: 全项目用工合规性手续办理 Handling of compliance procedures for the entire project's employment | D33: 600MW/750MWp | E33: Wp | F33: 750000000 | G33: 0.02 | H33: =F33*G33/10000 -> 1500
B34: 17 | C34: 运费 Freight | E34: Wp | F34: 750000000 | G34: 0.01 | H34: =F34*G34/10000 -> 750
B35: 18 | C35: 现场管理费 Management fee | E35: Wp | F35: 750000000 | G35: 0.02 | H35: =F35*G35/10000 -> 1500
B36: 19 | C36: 交通费等 Transportation fees, etc | E36: Wp | F36: 750000000 | G36: 0.01 | H36: =F36*G36/10000 -> 750
B37: 20 | C37: 合计(二) Total(II) | H37: =SUM(H18:H36) -> 38625
B38: 三 III | C38: 华松电力集团股份有限公司
B39: 1 | C39: 主变压器(包括但不限于中性点成套装置、排油注氮灭火装置等附属配置) Main transformer (including but not limited to auxiliary configurations such as neutral point complete equipment, oil discharge and nitrogen injection fire extinguishing device, etc.) | D39: 600MW/750MWp，500KV | E39: Wp | F39: 750000000 | G39: 0.037 | H39: =F39*G39/10000 -> 2775 | I39: 所有税金(境内境外)、报关费、管理费、利润均包含在单价和合价之内。 Al1 taxes (domestic and overseas), customs clearance fees, management fees, and profits are in the unit price and total price.
B40: 2 | C40: SVG系统(成套装置) SVG system(Complete equipment) | D40: 600MW/750MWp，500KV | F40: 750000000 | G40: 0.011 | H40: =F40*G40/10000 -> 825
B41: 3 | C41: GIS系统(或AIS系统)(包括但不限于附属的出线套管支撑件、旁路隔离开关支撑件、汇控柜槽盒、避雷器支架、基础等等) GIS system (or AIS system)(Including but not limited to supporting components such as auxiliary outgoing conduit, bypass isolation switch, control cabinet tray, lightning arrester bracket, foundation, etc) | D41: 600MW/750MWp，500KV | E41: Wp | F41: 750000000 | G41: 0.015 | H41: =F41*G41/10000 -> 1125
B42: 4 | C42: 钢构架及避雷针 Steel frame and lightning rod | D42: 600MW/750MWp，500KV | E42: Wp | F42: 750000000 | G42: 0.004 | H42: =F42*G42/10000 -> 300
B43: 5 | C43: 高压系统(包括但不限于氧化锌避雷器、电压互感器、电流互感器、耦合电容器、阻波器、隔离开关、接地开关、高压开关、35kV开关柜、预制舱室、接地变及小电阻成套装置、母线、导体和导线(线缆)、金具、套管、支柱绝缘子、防雷接地系统、防孤岛保护装置、备品备件等等) High voltage system(including but not limited to zinc oxide lightning arresters, voltage transformers, current transformers, coupling capacitors, wave blockers, isolating switches, high voltage switches,35kV switchgear, prefabricated cabins, grounding transformers and small resistance complete sets of equipment, busbars, conductors and wires, fittings, lightning protection grounding systems, etc.) | D43: 600MW/750MWp，500KV | E43: Wp | F43: 750000000 | G43: 0.02 | H43: =F43*G43/10000 -> 1500
...

Sheet 边界条件
B2: 参数汇总表（不含储能投资）
B3: 序号 | C3: 项目 | D3: 单位 | E3: 数值 | F3: 备注
B4: 一 | C4: 工程概况
B5: 1 | C5: 光伏系统容量 | D5: MW | E5: =假设及结论!F13*10 -> 750 | F5: 直流侧容量
B6: 2 | C6: 工期 | D6: 月 | E6: 12
B7: 3 | C7: 项目运行期 | D7: 年 | E7: =假设及结论!H13 -> 25
B8: 二 | C8: 投资类参数
B9: 1 | C9: 单位千瓦静态投资 | D9: 元/kW | E9: =(假设及结论!C13-资金筹措!C8)/假设及结论!F13 -> 3311.1218 | F9: 不含储能
B10: 2 | C10: 静态投资 | D10: 万元 | E10: =假设及结论!C15 -> 247200 | F10: 不含储能
B11: 3 | C11: 动态投资 | D11: 万元 | E11: =假设及结论!C13 -> 251649.6 | F11: 不含储能
B12: 4 | C12: 资本金比例 | D12: % | E12: =假设及结论!Q30*100 -> 30
B13: 5 | C13: 可抵扣税金 | D13: 万元 | E13: =销售收入!C38 -> 0
B14: 6 | C14: 流动资金单位千瓦指标 | D14: 元/kW | E14: =MID(假设及结论!$B$32,18,2) -> 20
B15: 三 | C15: 成本类参数
B16: 1 | C16: 贷款情况
B17: 1.1 | C17: 银行1还款期限 | D17: 年 | E17: =假设及结论!O30 -> 15
C18: 还本付息方式 | E18: 等额还本利息照付
C19: 长期贷款利率 | D19: % | E19: =假设及结论!P30*100 -> 3.6
B20: 1.2 | C20: 流动资金贷款利率 | D20: % | E20: =假设及结论!N30*100 -> 3.45
B21: 2 | C21: 折旧
B22: 2.1 | C22: 光伏系统折旧年限 | D22: 年 | E22: =假设及结论!G33 -> 25 | F22: 税法规定
B23: 2.2 | C23: 光伏系统残值率 | D23: % | E23: =假设及结论!H33*100 -> 5
B24: 3 | C24: 光伏系统修理费 | D24: 元/kW | E24: =假设及结论!O24 -> 9.2
B25: 4 | C25: 光伏系统保险费 | D25: % | E25: 0 | F25: 运维已包含，暂未单独考虑
B26: 5 | C26: 人工成本
B27: 5.1 | C27: 定员标准 | D27: 人 | E27: =假设及结论!D21 -> 20
B28: 5.2 | C28: 人均年工资 | D28: 万元 | E28: =假设及结论!E21*(1+假设及结论!F21) -> 24.992
B29: 6 | C29: 材料费 | D29: 元/kW | E29: =假设及结论!M24 -> 10
B30: 7 | C30: 其他费用
B31: 7.1 | C31: 其他费用 | D31: 元/kW | E31: =假设及结论!Q24 -> 8.5 | H31: 实际
B32: 7.2 | C32: 租地费用（每年） | D32: 万元 | E32: =总成本!E10 -> 155.3202 | F32: =假设及结论!G21&"公顷，"&假设及结论!H21&"美元/公顷/年，共计租地"&假设及结论!G15&"年" -> 1232.7公顷，180美元/公顷/年，共计租地25年 | H32: 178
B33: 7.3 | C33: 一次性土地补偿费 | D33: 万元 | E33: =假设及结论!K21 -> 33.52944 | F33: =假设及结论!J21&"美元/公顷" -> 272美元/公顷 | H33: 272
B34: 四 | C34: 收益类参数
B35: 1 | C35: 首年利用小时数 | D35: h | E35: =假设及结论!I13 -> 1545 | F35: 第一年衰减1%，后续每年0.4%
B36: 2 | C36: 上网电价（不含增值税） | D36: 元/kWh | E36: =假设及结论!I15 -> 0.35 | F36: =TEXT(E36/假设及结论!I21,"##0.##0"&" 美分") -> 0.050 美分
C37: 电网公司收电力服务费 | D37: 元/kWh | E37: =假设及结论!M13 -> 0 | F37: 类似国内的辅助服务费，结算时需要在PPA中扣除
B38: 3 | C38: 增值税税率 | D38: % | E38: =假设及结论!H30 -> 0.12 | F38: 进口豁免征收。
B39: 4 | C39: 所得税税率 | D39: % | E39: =假设及结论!B30 -> 0.1 | F39: 在吉尔吉斯，称为“利润税”“利得税”，豁免
B40: 5 | C40: 城市维护建设税 | D40: % | E40: =假设及结论!F30 -> 0 | F40: 无
B41: 6 | C41: 教育费附加 | D41: % | E41: =假设及结论!G30 -> 0 | F41: 无
...

Sheet 损益表
A2: 利 润 和 利 润 分 配 表
W3: 单位:万元
A4: 序 | B4: 年份 名称 | C4: 合计 | D4: 建设经营期
A5: 号 | D5: 1 | E5: 2 | F5: 3 | G5: 4 | H5: 5 | I5: 6 | J5: 7 | K5: 8 | L5: 9 | M5: 10 | N5: 11 | O5: 12 | P5: 13 | Q5: 14 | R5: 15 | S5: 16 | T5: 17 | U5: 18 | V5: 19 | W5: 20 | X5: 21 | Y5: 22 | Z5: 23 | AA5: 24 | AB5: 25 | AC5: 26 | AD5: 27
A6: 1 | B6: 营业收入（不含增值税和销售税） | C6: =SUM(D6:AD6) -> 940024.39 | E6: =销售收入!E6 -> 39737.25 | F6: =销售收入!F6 -> 39339.878 | G6: =销售收入!G6 -> 39180.929 | H6: =销售收入!H6 -> 39021.98 | I6: =销售收入!I6 -> 38863.031 | J6: =销售收入!J6 -> 38704.082 | K6: =销售收入!K6 -> 38545.132 | L6: =销售收入!L6 -> 38386.183 | ... AD6: =销售收入!AD6 -> 0
A7: 2 | B7: 增值税实际收入 | C7: =SUM(D7:AD7) -> 0
A8: 3 | B8: 营业税金及附加 | C8: =SUM(D8:AD8) -> 9400.2439 | E8: =销售收入!E30 -> 397.3725 | F8: =销售收入!F30 -> 393.39878 | G8: =销售收入!G30 -> 391.80928 | H8: =销售收入!H30 -> 390.21979 | I8: =销售收入!I30 -> 388.63031 | J8: =销售收入!J30 -> 387.04082 | K8: =销售收入!K30 -> 385.45132 | L8: =销售收入!L30 -> 383.86183 | ... AD8: =销售收入!AD30 -> 0
A9: 4 | B9: 总成本费用 | C9: =SUM(D9:AD9) -> 345351.78 | D9: =总成本!D21 -> 0 | E9: =总成本!E21 -> 19840.658 | F9: =总成本!F21 -> 19395.106 | G9: =总成本!G21 -> 18949.556 | H9: =总成本!H21 -> 18504.008 | I9: =总成本!I21 -> 18058.463 | J9: =总成本!J21 -> 17879.366 | K9: =总成本!K21 -> 17433.825 | ... AD9: =总成本!AD21 -> 155.3202
A10: 5 | B10: 利润总额（1+2-3-4） | C10: =SUM(D10:AD10) -> 585272.37 | D10: =D6+D7-D8-D9 -> 0 | E10: =E6+E7-E8-E9 -> 19499.219 | F10: =F6+F7-F8-F9 -> 19551.373 | G10: =G6+G7-G8-G9 -> 19839.563 | H10: =H6+H7-H8-H9 -> 20127.751 | I10: =I6+I7-I8-I9 -> 20415.938 | J10: =J6+J7-J8-J9 -> 20437.674 | K10: =K6+K7-K8-K9 -> 20725.856 | ... AD10: =AD6+AD7-AD8-AD9 -> -155.3202
A11: 6 | B11: 税前弥补以前年度亏损 | C11: =SUM(D11:AD11) -> 0 | E11: =IF(AND(SUM($D$14:D$14)<0,E5<ConstructPeriod+5),SUM($D$14:D$14),0) -> 0 | F11: =IF(AND(SUM($D$14:E$14)<0,F5<ConstructPeriod+5),SUM($D$14:E$14),0) -> 0 | G11: =IF(AND(SUM($D$14:F$14)<0,G5<ConstructPeriod+5),SUM($D$14:F$14),0) -> 0 | H11: =IF(AND(SUM($D$14:G$14)<0,H5<ConstructPeriod+5),SUM($D$14:G$14),0) -> 0 | I11: =IF(AND(SUM($D$14:H$14)<0,I5<ConstructPeriod+5),SUM($D$14:H$14),0) -> 0 | J11: =IF(AND(SUM($D$14:I$14)<0,J5<ConstructPeriod+5),SUM($D$14:I$14),0) -> 0 | K11: =IF(AND(SUM($D$14:J$14)<0,K5<ConstructPeriod+5),SUM($D$14:J$14),0) -> 0 | L11: =IF(AND(SUM($D$14:K$14)<0,L5<ConstructPeriod+5),SUM($D$14:K$14),0) -> 0 | ... AD11: =IF(AND(SUM($D$14:AC$14)<0,AD5<ConstructPeriod+5),SUM($D$14:AC$14),0) -> 0
A12: 7 | B12: 应纳税所得额（5+6） | C12: =SUM(D12:AD12) -> 585427.69 | E12: =IF(E10+E11<0,0,E10+E11) -> 19499.219 | F12: =IF(F10+F11<0,0,F10+F11) -> 19551.373 | G12: =IF(G10+G11<0,0,G10+G11) -> 19839.563 | H12: =IF(H10+H11<0,0,H10+H11) -> 20127.751 | I12: =IF(I10+I11<0,0,I10+I11) -> 20415.938 | J12: =IF(J10+J11<0,0,J10+J11) -> 20437.674 | K12: =IF(K10+K11<0,0,K10+K11) -> 20725.856 | L12: =IF(L10+L11<0,0,L10+L11) -> 21014.036 | ... AD12: =IF(AD10+AD11<0,0,AD10+AD11) -> 0
A13: 8 | B13: ="所得税（"&假设及结论!B30*100&"%)"&" 减免"&假设及结论!D30&"年" -> 所得税（10%) 减免10年 | C13: =SUM(D13:AD13) -> 40251.406 | E13: =IF(假设及结论!$C$30="YES",IF(E5<=ConstructPeriod+3,0,IF(E5<=ConstructPeriod+6,E12*假设及结论!$B$30*0.5,E12*假设及结论!$B$30)),E12*IF(E5>10,假设及结论!$B$30,0)) -> 0 | F13: =IF(假设及结论!$C$30="YES",IF(F5<=ConstructPeriod+3,0,IF(F5<=ConstructPeriod+6,F12*假设及结论!$B$30*0.5,F12*假设及结论!$B$30)),F12*IF(F5>10,假设及结论!$B$30,0)) -> 0 | G13: =IF(假设及结论!$C$30="YES",IF(G5<=ConstructPeriod+3,0,IF(G5<=ConstructPeriod+6,G12*假设及结论!$B$30*0.5,G12*假设及结论!$B$30)),G12*IF(G5>10,假设及结论!$B$30,0)) -> 0 | H13: =IF(假设及结论!$C$30="YES",IF(H5<=ConstructPeriod+3,0,IF(H5<=ConstructPeriod+6,H12*假设及结论!$B$30*0.5,H12*假设及结论!$B$30)),H12*IF(H5>10,假设及结论!$B$30,0)) -> 0 | I13: =IF(假设及结论!$C$30="YES",IF(I5<=ConstructPeriod+3,0,IF(I5<=ConstructPeriod+6,I12*假设及结论!$B$30*0.5,I12*假设及结论!$B$30)),I12*IF(I5>10,假设及结论!$B$30,0)) -> 0 | J13: =IF(假设及结论!$C$30="YES",IF(J5<=ConstructPeriod+3,0,IF(J5<=ConstructPeriod+6,J12*假设及结论!$B$30*0.5,J12*假设及结论!$B$30)),J12*IF(J5>10,假设及结论!$B$30,0)) -> 0 | K13: =IF(假设及结论!$C$30="YES",IF(K5<=ConstructPeriod+3,0,IF(K5<=ConstructPeriod+6,K12*假设及结论!$B$30*0.5,K12*假设及结论!$B$30)),K12*IF(K5>10,假设及结论!$B$30,0)) -> 0 | L13: =IF(假设及结论!$C$30="YES",IF(L5<=ConstructPeriod+3,0,IF(L5<=ConstructPeriod+6,L12*假设及结论!$B$30*0.5,L12*假设及结论!$B$30)),L12*IF(L5>10,假设及结论!$B$30,0)) -> 0 | ... AD13: =IF(假设及结论!$C$30="YES",IF(AD5<=ConstructPeriod+3,0,IF(AD5<=ConstructPeriod+6,AD12*假设及结论!$B$30*0.5,AD12*假设及结论!$B$30)),AD12*IF(AD5>10,假设及结论!$B$30,0)) -> 0
A14: 9 | B14: 净利润（5-8） | C14: =SUM(D14:AD14) -> 545020.96 | D14: =D10-D13 -> 0 | E14: =E10-E13 -> 19499.219 | F14: =F10-F13 -> 19551.373 | G14: =G10-G13 -> 19839.563 | H14: =H10-H13 -> 20127.751 | I14: =I10-I13 -> 20415.938 | J14: =J10-J13 -> 20437.674 | K14: =K10-K13 -> 20725.856 | ... AD14: =AD10-AD13 -> -155.3202
A15: 10 | B15: 税后弥补之前亏损 | D15: 0 | E15: =IF(SUM($D$14:D14)<0,SUM($D$14:D14),0) -> 0 | F15: =IF(SUM($D$14:E14)<0,SUM($D$14:E14),0) -> 0 | G15: =IF(SUM($D$14:F14)<0,SUM($D$14:F14),0) -> 0 | H15: =IF(SUM($D$14:G14)<0,SUM($D$14:G14),0) -> 0 | I15: =IF(SUM($D$14:H14)<0,SUM($D$14:H14),0) -> 0 | J15: =IF(SUM($D$14:I14)<0,SUM($D$14:I14),0) -> 0 | K15: =IF(SUM($D$14:J14)<0,SUM($D$14:J14),0) -> 0 | L15: =IF(SUM($D$14:K14)<0,SUM($D$14:K14),0) -> 0 | ... AD15: =IF(SUM($D$14:AC14)<0,SUM($D$14:AC14),0) -> 0
A16: 11 | B16: 期初未分配利润 | D16: =IF(C20<0,0,IF(D5-ConstructPeriod>OperationPeriod,0,C20)) -> 0 | E16: =IF(D20<0,0,IF(E5-ConstructPeriod>OperationPeriod,0,D20)) -> 0 | F16: =IF(E20<0,0,IF(F5-ConstructPeriod>OperationPeriod,0,E20)) -> 16574.337 | G16: =IF(F20<0,0,IF(G5-ConstructPeriod>OperationPeriod,0,F20)) -> 33193.003 | H16: =IF(G20<0,0,IF(H5-ConstructPeriod>OperationPeriod,0,G20)) -> 50056.632 | I16: =IF(H20<0,0,IF(I5-ConstructPeriod>OperationPeriod,0,H20)) -> 67165.221 | J16: =IF(I20<0,0,IF(J5-ConstructPeriod>OperationPeriod,0,I20)) -> 84518.768 | K16: =IF(J20<0,0,IF(K5-ConstructPeriod>OperationPeriod,0,J20)) -> 101890.79 | ... AD16: =IF(AC20<0,0,IF(AD5-ConstructPeriod>OperationPeriod,0,AC20)) -> 0
A17: 12 | B17: 可供分配利润（9+11） | D17: =D14+D15 -> 0 | E17: =E14+E15 -> 19499.219 | F17: =F14+F15 -> 19551.373 | G17: =G14+G15 -> 19839.563 | H17: =H14+H15 -> 20127.751 | I17: =I14+I15 -> 20415.938 | J17: =J14+J15 -> 20437.674 | K17: =K14+K15 -> 20725.856 | ... AD17: =AD14+AD15 -> -155.3202
A18: 13 | B18: ="提取法定盈余公积金("&假设及结论!M33*100&"%)" -> 提取法定盈余公积金(10%) | D18: =IF(D17<0,0,IF(SUM(D$17:$E17)/10<=资金筹措!$F$12/2,D17*假设及结论!$M$33,0)) -> 0 | E18: =IF(E17<0,0,IF(SUM(E$17:$E17)/10<=资金筹措!$F$12/2,E17*假设及结论!$M$33,0)) -> 1949.9219 | F18: =IF(F17<0,0,IF(SUM($E$17:F17)/10<=资金筹措!$F$12/2,F17*假设及结论!$M$33,0)) -> 1955.1373 | G18: =IF(G17<0,0,IF(SUM($E$17:G17)/10<=资金筹措!$F$12/2,G17*假设及结论!$M$33,0)) -> 1983.9563 | H18: =IF(H17<0,0,IF(SUM($E$17:H17)/10<=资金筹措!$F$12/2,H17*假设及结论!$M$33,0)) -> 2012.7751 | I18: =IF(I17<0,0,IF(SUM($E$17:I17)/10<=资金筹措!$F$12/2,I17*假设及结论!$M$33,0)) -> 2041.5938 | J18: =IF(J17<0,0,IF(SUM($E$17:J17)/10<=资金筹措!$F$12/2,J17*假设及结论!$M$33,0)) -> 2043.7674 | K18: =IF(K17<0,0,IF(SUM($E$17:K17)/10<=资金筹措!$F$12/2,K17*假设及结论!$M$33,0)) -> 2072.5856 | L18: =IF(L17<0,0,IF(SUM($E$17:L17)/10<=资金筹措!$F$12/2,L17*假设及结论!$M$33,0)) -> 2101.4036 | M18: =IF(M17<0,0,IF(SUM($E$17:M17)/10<=资金筹措!$F$12/2,M17*假设及结论!$M$33,0)) -> 2130.2214 | ... AD18: =IF(AD17<0,0,IF(SUM($E$17:AD17)/10<=资金筹措!$F$12/2,AD17*假设及结论!$M$33,0)) -> 0
A19: 14 | B19: ="反税基要求/预扣税 ( "&假设及结论!E30*100&" %)" -> 反税基要求/预扣税 ( 5 %) | C19: =SUM(D19:AD19) -> 27251.048 | E19: =E14*假设及结论!$E$30 -> 974.96097 | F19: =F14*假设及结论!$E$30 -> 977.56863 | G19: =G14*假设及结论!$E$30 -> 991.97815 | H19: =H14*假设及结论!$E$30 -> 1006.3876 | I19: =I14*假设及结论!$E$30 -> 1020.7969 | J19: =J14*假设及结论!$E$30 -> 1021.8837 | K19: =K14*假设及结论!$E$30 -> 1036.2928 | L19: =L14*假设及结论!$E$30 -> 1050.7018 | ... AD19: =AD14*假设及结论!$E$30 -> -7.76601
A20: 15 | B20: 可供投资者分配的利润（11+12-13-14） | D20: =IF(D5-ConstructPeriod>OperationPeriod,0,D16+D17-D18) -> 0 | E20: =IF(E5-ConstructPeriod>OperationPeriod,0,E16+E17-E18-E19) -> 16574.337 | F20: =IF(F5-ConstructPeriod>OperationPeriod,0,F16+F17-F18-F19) -> 33193.003 | G20: =IF(G5-ConstructPeriod>OperationPeriod,0,G16+G17-G18-G19) -> 50056.632 | H20: =IF(H5-ConstructPeriod>OperationPeriod,0,H16+H17-H18-H19) -> 67165.221 | I20: =IF(I5-ConstructPeriod>OperationPeriod,0,I16+I17-I18-I19) -> 84518.768 | J20: =IF(J5-ConstructPeriod>OperationPeriod,0,J16+J17-J18-J19) -> 101890.79 | K20: =IF(K5-ConstructPeriod>OperationPeriod,0,K16+K17-K18-K19) -> 119507.77 | L20: =IF(L5-ConstructPeriod>OperationPeriod,0,L16+L17-L18-L19) -> 137369.7 | ... AD20: =IF(AD5-ConstructPeriod>OperationPeriod,0,AD16+AD17-AD18-AD19) -> 0
A21: 16 | B21: 应付优先股股利
A22: 17 | B22: 提取任意盈余公积金
A23: 18 | B23: 应付普通股股利（15-16-17） | D23: =D20-D21-D22 -> 0 | E23: =E20-E21-E22 -> 16574.337 | F23: =F20-F21-F22 -> 33193.003 | G23: =G20-G21-G22 -> 50056.632 | H23: =H20-H21-H22 -> 67165.221 | I23: =I20-I21-I22 -> 84518.768 | J23: =J20-J21-J22 -> 101890.79 | K23: =K20-K21-K22 -> 119507.77 | ... AD23: =AD20-AD21-AD22 -> 0
A24: 19 | B24: 各投资方利润分配
A25: 20 | B25: 未分配利润（15-16-17-19） | C25: =MAX(D25:AD25) -> 477587.76 | D25: =D23-D24 -> 0 | E25: =E23-E24 -> 16574.337 | F25: =F23-F24 -> 33193.003 | G25: =G23-G24 -> 50056.632 | H25: =H23-H24 -> 67165.221 | I25: =I23-I24 -> 84518.768 | J25: =J23-J24 -> 101890.79 | K25: =K23-K24 -> 119507.77 | ... AD25: =AD23-AD24 -> 0
A26: 21 | B26: 息税前利润（利润总额+ 利息支出） | C26: =SUM(D26:AD26) -> 638988.15 | D26: =D10+总成本!D20 -> 0 | E26: =E10+总成本!E20 -> 26213.693 | F26: =F10+总成本!F20 -> 25818.215 | G26: =G10+总成本!G20 -> 25658.773 | H26: =H10+总成本!H20 -> 25499.33 | I26: =I10+总成本!I20 -> 25339.885 | J26: =J10+总成本!J20 -> 24913.99 | K26: =K10+总成本!K20 -> 24754.54 | ... AD26: =AD10+总成本!AD20 -> -155.3202
A27: 22 | B27: 息税折旧摊销前利润（息税前利润+折旧+摊销） | C27: =SUM(D27:AD27) -> 841488.14 | D27: =D26+总成本!D18+总成本!D19 -> 0 | E27: =E26+总成本!E18+总成本!E19 -> 36338.692 | F27: =F26+总成本!F18+总成本!F19 -> 35943.214 | G27: =G26+总成本!G18+总成本!G19 -> 35783.773 | H27: =H26+总成本!H18+总成本!H19 -> 35624.33 | I27: =I26+总成本!I18+总成本!I19 -> 35464.884 | J27: =J26+总成本!J18+总成本!J19 -> 35038.99 | K27: =K26+总成本!K18+总成本!K19 -> 34879.54 | ... AD27: =AD26+总成本!AD18+总成本!AD19 -> -155.3202
E29: =IF(假设及结论!C30="YES",IF(E5<=ConstructPeriod+3,0,IF(E5<=ConstructPeriod+6,E12*假设及结论!$B$30*0.5,E12*假设及结论!$B$30)),E12*假设及结论!$B$30) -> 1949.9219
C30: 平均值
B31: 补贴有延迟时的净利润 | C31: =SUM(E31:AD31)/OperationPeriod -> 3771.0884 | E31: =IF(假设及结论!$F$15>1,E10,E31) -> -969.21797 | F31: =IF(假设及结论!$F$15>1,F10,F31) -> -792.93351 | G31: =IF(假设及结论!$F$15>1,G10,G31) -> 2628.7392 | H31: =IF(假设及结论!$F$15>1,H10,H31) -> 3140.544 | I31: =IF(假设及结论!$F$15>1,I10,I31) -> 3639.3693 | J31: =IF(假设及结论!$F$15>1,J10,J31) -> 3583.9733 | K31: =IF(假设及结论!$F$15>1,K10,K31) -> 3758.7156 | L31: =IF(假设及结论!$F$15>1,L10,L31) -> 3933.1212 | ... AD31: =IF(假设及结论!$F$15>1,AD10,AD31) -> 5.9117156e-13
B32: 补贴无延迟时的净利润 | C32: =SUM(E32:AD32)/OperationPeriod -> 23410.895 | E32: =IF(假设及结论!$F$15=1,E10,E32) -> 19499.219 | F32: =IF(假设及结论!$F$15=1,F10,F32) -> 19551.373 | G32: =IF(假设及结论!$F$15=1,G10,G32) -> 19839.563 | H32: =IF(假设及结论!$F$15=1,H10,H32) -> 20127.751 | I32: =IF(假设及结论!$F$15=1,I10,I32) -> 20415.938 | J32: =IF(假设及结论!$F$15=1,J10,J32) -> 20437.674 | K32: =IF(假设及结论!$F$15=1,K10,K32) -> 20725.856 | L32: =IF(假设及结论!$F$15=1,L10,L32) -> 21014.036 | ... AD32: =IF(假设及结论!$F$15=1,AD10,AD32) -> -155.3202
B33: 补贴无延迟时的所得税 | E33: =IF(假设及结论!$F$15=1,E13,E33) -> 0 | F33: =IF(假设及结论!$F$15=1,F13,F33) -> 0 | G33: =IF(假设及结论!$F$15=1,G13,G33) -> 0 | H33: =IF(假设及结论!$F$15=1,H13,H33) -> 0 | I33: =IF(假设及结论!$F$15=1,I13,I33) -> 0 | J33: =IF(假设及结论!$F$15=1,J13,J33) -> 0 | K33: =IF(假设及结论!$F$15=1,K13,K33) -> 0 | L33: =IF(假设及结论!$F$15=1,L13,L33) -> 0 | ... AD33: =IF(假设及结论!$F$15=1,AD13,AD33) -> 0
B34: 付息 | E34: =还本付息!E29 -> 6714.4734 | F34: =还本付息!F29 -> 6266.8418 | G34: =还本付息!G29 -> 5819.2103 | H34: =还本付息!H29 -> 5371.5787 | I34: =还本付息!I29 -> 4923.9472 | J34: =还本付息!J29 -> 4476.3156 | K34: =还本付息!K29 -> 4028.684 | L34: =还本付息!L29 -> 3581.0525 | ... AD34: =还本付息!AD29 -> -1.7025741e-12
B35: 期初负债余额 | E35: =还本付息!E26 -> 186513.15 | F35: =还本付息!F26 -> 174078.94 | G35: =还本付息!G26 -> 161644.73 | H35: =还本付息!H26 -> 149210.52 | I35: =还本付息!I26 -> 136776.31 | J35: =还本付息!J26 -> 124342.1 | K35: =还本付息!K26 -> 111907.89 | L35: =还本付息!L26 -> 99473.68 | ... AD35: =还本付息!AD26 -> -4.7293724e-11
B36: 实际净现金流 | E36: =资本金现金流!D21 -> 16215.048 | F36: =资本金现金流!E21 -> 16264.594 | G36: =资本金现金流!F21 -> 16538.374 | H36: =资本金现金流!G21 -> 16812.153 | I36: =资本金现金流!H21 -> 17085.93 | J36: =资本金现金流!I21 -> 17106.58 | K36: =资本金现金流!J21 -> 17380.353 | L36: =资本金现金流!K21 -> 17654.124 | ... AD36: =资本金现金流!AC21 -> -147.55419
B37: 年平均EVA | C37: =SUM(E37:AD37)/OperationPeriod -> 15781.91 | E37: =IF(AND(E5>ConstructPeriod,E5<=OperationPeriod+1),E32+E34-E33-(资金筹措!$C$12+E35-E36)*WACC,0) -> 9032.9628 | F37: =IF(AND(F5>ConstructPeriod,F5<=OperationPeriod+1),F32+F34-F33-(资金筹措!$C$12+F35-F36)*WACC,0) -> 9489.5007 | G37: =IF(AND(G5>ConstructPeriod,G5<=OperationPeriod+1),G32+G34-G33-(资金筹措!$C$12+G35-G36)*WACC,0) -> 10197.38 | H37: =IF(AND(H5>ConstructPeriod,H5<=OperationPeriod+1),H32+H34-H33-(资金筹措!$C$12+H35-H36)*WACC,0) -> 10905.257 | I37: =IF(AND(I5>ConstructPeriod,I5<=OperationPeriod+1),I32+I34-I33-(资金筹措!$C$12+I35-I36)*WACC,0) -> 11613.132 | J37: =IF(AND(J5>ConstructPeriod,J5<=OperationPeriod+1),J32+J34-J33-(资金筹措!$C$12+J35-J36)*WACC,0) -> 12037.281 | K37: =IF(AND(K5>ConstructPeriod,K5<=OperationPeriod+1),K32+K34-K33-(资金筹措!$C$12+K35-K36)*WACC,0) -> 12745.151 | L37: =IF(AND(L5>ConstructPeriod,L5<=OperationPeriod+1),L32+L34-L33-(资金筹措!$C$12+L35-L36)*WACC,0) -> 13453.02 | ... AD37: =IF(AND(AD5>ConstructPeriod,AD5<=OperationPeriod+1),AD32+AD34-AD33-(资金筹措!$C$12+AD35-AD36)*WACC,0) -> 0
C38: EVA = 税后净营业利润（NOPAT）-（【加权平均资本成本】WACC*【投资资本总额】TC） | N38: 税后净营业利润（NOPAT） = 营业利润+ 财务费用+ 投资收益- EVA税收调整
N39: EVA税收调整 = 利润表上所得税 + 税率 ×（财务费用 + 营业外支出 - 营业外收入）
B40: 折现率 | C40: 0.08 | D40: 0.09 | E40: 0.1 | F40: 0.11 | G40: 0.12 | H40: 0.13
B41: 股权价值 | C41: =NPV(C40,$E$17:$AD$17) -> 221880.74 | D41: =NPV(D40,$E$17:$AD$17) -> 203330.52 | E41: =NPV(E40,$E$17:$AD$17) -> 187196.01 | F41: =NPV(F40,$E$17:$AD$17) -> 173092.64 | G41: =NPV(G40,$E$17:$AD$17) -> 160704.7 | H41: =NPV(H40,$E$17:$AD$17) -> 149772.05

Sheet 全部投资现金流
A2: 项目投资现金流量表
W3: 单位:万元
A4: 序 | B4: 年份 名称 | C4: 建设营运期
A5: 号 | C5: 1 | D5: 2 | E5: 3 | F5: 4 | G5: 5 | H5: 6 | I5: 7 | J5: 8 | K5: 9 | L5: 10 | M5: 11 | N5: 12 | O5: 13 | P5: 14 | Q5: 15 | R5: 16 | S5: 17 | T5: 18 | U5: 19 | V5: 20 | W5: 21 | X5: 22 | Y5: 23 | Z5: 24 | AA5: 25 | AB5: 26 | AC5: 27
A6: 1 | B6: “增量”现金流入 | C6: =SUM(C7:C10) -> 0 | D6: =SUM(D7:D10) -> 39737.25 | E6: =SUM(E7:E10) -> 39339.878 | F6: =SUM(F7:F10) -> 39180.929 | G6: =SUM(G7:G10) -> 39021.98 | H6: =SUM(H7:H10) -> 38863.031 | I6: =SUM(I7:I10) -> 38704.082 | J6: =SUM(J7:J10) -> 38545.132 | ... AC6: =SUM(AC7:AC10) -> 0
A7: 1.1 | B7: 营业收入 | C7: =损益表!D6 -> 0 | D7: =销售收入!E6 -> 39737.25 | E7: =销售收入!F6 -> 39339.878 | F7: =销售收入!G6 -> 39180.929 | G7: =销售收入!H6 -> 39021.98 | H7: =销售收入!I6 -> 38863.031 | I7: =销售收入!J6 -> 38704.082 | J7: =销售收入!K6 -> 38545.132 | K7: =销售收入!L6 -> 38386.183 | ... AC7: =销售收入!AD6 -> 0
A8: 1.2 | B8: 固定资产增值税抵扣 | C8: =资本金现金流!C8 -> 0 | D8: =销售收入!E40 -> 0 | E8: =销售收入!F40 -> 0 | F8: =销售收入!G40 -> 0 | G8: =销售收入!H40 -> 0 | H8: =销售收入!I40 -> 0 | I8: =销售收入!J40 -> 0 | J8: =销售收入!K40 -> 0 | K8: =销售收入!L40 -> 0 | ... AC8: =销售收入!AD40 -> 0
A9: 1.3 | B9: 回收固定资产余值 | M9: =资本金现金流!M9 -> 0 | N9: =资本金现金流!N9 -> 0 | O9: =资本金现金流!O9 -> 0 | P9: =资本金现金流!P9 -> 0 | Q9: =资本金现金流!Q9 -> 0 | S9: =资本金现金流!S9 -> 0 | U9: =资本金现金流!U9 -> 0
A10: 1.4 | B10: 回收流动资金 | F10: =E10*3 -> 0 | G10: =F10 -> 0 | I10: =H10 -> 0 | J10: =I10 -> 0 | K10: =J10 -> 0 | L10: =K10 -> 0 | M10: =L10 -> 0 | N10: =M10 -> 0 | O10: =N10 -> 0 | P10: =O10 -> 0 | ... AC10: =AB10 -> 0
A11: 2 | B11: “增量”现金流出 | C11: =SUM(C12:C16) -> 264631.9 | D11: =SUM(D12:D16) -> 3398.5576 | E11: =SUM(E12:E16) -> 3396.6634 | F11: =SUM(F12:F16) -> 3397.1556 | G11: =SUM(G12:G16) -> 3397.6498 | H11: =SUM(H12:H16) -> 3398.1462 | I11: =SUM(I12:I16) -> 3665.0919 | J11: =SUM(J12:J16) -> 3665.5924 | ... AC11: =SUM(AC12:AC16) -> 155.3202
A12: 2.1 | B12: 建设投资（不含建设期利息） | C12: =资金筹措!C7 -> 263131.9 | D12: =资金筹措!D7 -> 0
A13: 2.2 | B13: 流动资金 | C13: =资金筹措!C9 -> 1500 | D13: =资金筹措!D9 -> 0 | E13: =资金筹措!E9 -> 0
A14: 2.3 | B14: 经营成本 | C14: =总成本!D17 -> 0 | D14: =总成本!E17 -> 3001.1851 | E14: =总成本!F17 -> 3003.2646 | F14: =总成本!G17 -> 3005.3463 | G14: =总成本!H17 -> 3007.43 | H14: =总成本!I17 -> 3009.5159 | I14: =总成本!J17 -> 3278.0511 | J14: =总成本!K17 -> 3280.1411 | ... AC14: =总成本!AD17 -> 155.3202
A15: 2.4 | B15: 营业税金及附加 | C15: =损益表!D8 -> 0 | D15: =损益表!E8 -> 397.3725 | E15: =损益表!F8 -> 393.39878 | F15: =损益表!G8 -> 391.80928 | G15: =损益表!H8 -> 390.21979 | H15: =损益表!I8 -> 388.63031 | I15: =损益表!J8 -> 387.04082 | J15: =损益表!K8 -> 385.45132 | ... AC15: =损益表!AD8 -> 0
A16: 2.5 | B16: 维持运营投资
A17: 3 | B17: 所得税前“增量”净现金流量 | C17: =C6-C11 -> -264631.9 | D17: =D6-D11 -> 36338.692 | E17: =E6-E11 -> 35943.214 | F17: =F6-F11 -> 35783.773 | G17: =G6-G11 -> 35624.33 | H17: =H6-H11 -> 35464.884 | I17: =I6-I11 -> 35038.99 | J17: =J6-J11 -> 34879.54 | ... AC17: =AC6-AC11 -> -155.3202
A18: 4 | B18: 累计所得税前“增量”净现金流量 | C18: =C17 -> -264631.9 | D18: =IF(D17=0,0,C18+D17) -> -228293.2 | E18: =IF(E17=0,0,D18+E17) -> -192349.99 | F18: =IF(F17=0,0,E18+F17) -> -156566.22 | G18: =IF(G17=0,0,F18+G17) -> -120941.89 | H18: =IF(H17=0,0,G18+H17) -> -85477.002 | I18: =IF(I17=0,0,H18+I17) -> -50438.012 | J18: =IF(J17=0,0,I18+J17) -> -15558.472 | K18: =IF(K17=0,0,J18+K17) -> 19161.616 | ... AC18: =IF(AC17=0,0,AB18+AC17) -> 576856.25
A19: 5 | B19: 调整“增量”所得税 | C19: =损益表!D13 -> 0 | D19: =IF(假设及结论!$C$30="YES",IF(D5<=ConstructPeriod+3,0,IF(D5<=ConstructPeriod+6,损益表!E26*假设及结论!$B$30*0.5,损益表!E26*假设及结论!$B$30)),损益表!E26*IF(E5>10,假设及结论!$B$30,0)) -> 0 | E19: =IF(假设及结论!$C$30="YES",IF(E5<=ConstructPeriod+3,0,IF(E5<=ConstructPeriod+6,损益表!F26*假设及结论!$B$30*0.5,损益表!F26*假设及结论!$B$30)),损益表!F26*IF(F5>10,假设及结论!$B$30,0)) -> 0 | F19: =IF(假设及结论!$C$30="YES",IF(F5<=ConstructPeriod+3,0,IF(F5<=ConstructPeriod+6,损益表!G26*假设及结论!$B$30*0.5,损益表!G26*假设及结论!$B$30)),损益表!G26*IF(G5>10,假设及结论!$B$30,0)) -> 0 | G19: =IF(假设及结论!$C$30="YES",IF(G5<=ConstructPeriod+3,0,IF(G5<=ConstructPeriod+6,损益表!H26*假设及结论!$B$30*0.5,损益表!H26*假设及结论!$B$30)),损益表!H26*IF(H5>10,假设及结论!$B$30,0)) -> 0 | H19: =IF(假设及结论!$C$30="YES",IF(H5<=ConstructPeriod+3,0,IF(H5<=ConstructPeriod+6,损益表!I26*假设及结论!$B$30*0.5,损益表!I26*假设及结论!$B$30)),损益表!I26*IF(I5>10,假设及结论!$B$30,0)) -> 0 | I19: =IF(假设及结论!$C$30="YES",IF(I5<=ConstructPeriod+3,0,IF(I5<=ConstructPeriod+6,损益表!J26*假设及结论!$B$30*0.5,损益表!J26*假设及结论!$B$30)),损益表!J26*IF(J5>10,假设及结论!$B$30,0)) -> 0 | J19: =IF(假设及结论!$C$30="YES",IF(J5<=ConstructPeriod+3,0,IF(J5<=ConstructPeriod+6,损益表!K26*假设及结论!$B$30*0.5,损益表!K26*假设及结论!$B$30)),损益表!K26*IF(K5>10,假设及结论!$B$30,0)) -> 0 | K19: =IF(假设及结论!$C$30="YES",IF(K5<=ConstructPeriod+3,0,IF(K5<=ConstructPeriod+6,损益表!L26*假设及结论!$B$30*0.5,损益表!L26*假设及结论!$B$30)),损益表!L26*IF(L5>10,假设及结论!$B$30,0)) -> 0 | ... AC19: =IF(假设及结论!$C$30="YES",IF(AC5<=ConstructPeriod+3,0,IF(AC5<=ConstructPeriod+6,损益表!AD26*假设及结论!$B$30*0.5,损益表!AD26*假设及结论!$B$30)),损益表!AD26*IF(AD5>10,假设及结论!$B$30,0)) -> 0
A20: 6 | B20: 调整“增量”反税基侵蚀补税/预扣税 | D20: =损益表!E19 -> 974.96097 | E20: =损益表!F19 -> 977.56863 | F20: =损益表!G19 -> 991.97815 | G20: =损益表!H19 -> 1006.3876 | H20: =损益表!I19 -> 1020.7969 | I20: =损益表!J19 -> 1021.8837 | J20: =损益表!K19 -> 1036.2928 | K20: =损益表!L19 -> 1050.7018 | ... AC20: =损益表!AD19 -> -7.76601
A21: 7 | B21: 所得税后“增量”净现金流量 | C21: =C17-C19 -> -264631.9 | D21: =D17-D19-D20 -> 35363.731 | E21: =E17-E19-E20 -> 34965.645 | F21: =F17-F19-F20 -> 34791.795 | G21: =G17-G19-G20 -> 34617.942 | H21: =H17-H19-H20 -> 34444.087 | I21: =I17-I19-I20 -> 34017.106 | J21: =J17-J19-J20 -> 33843.247 | K21: =K17-K19-K20 -> 33669.387 | ... AC21: =AC17-AC19-AC20 -> -147.55419
A22: 8 | B22: 累计所得税后“增量”净现金流量 | C22: =C21 -> -264631.9 | D22: =IF(D21=0,0,C22+D21) -> -229268.16 | E22: =IF(E21=0,0,D22+E21) -> -194302.52 | F22: =IF(F21=0,0,E22+F21) -> -159510.72 | G22: =IF(G21=0,0,F22+G21) -> -124892.78 | H22: =IF(H21=0,0,G22+H21) -> -90448.694 | I22: =IF(I21=0,0,H22+I21) -> -56431.588 | J22: =IF(J21=0,0,I22+J21) -> -22588.341 | K22: =IF(K21=0,0,J22+K21) -> 11081.046 | ... AC22: =IF(AC21=0,0,AB22+AC21) -> 505970.21
B25: 计算指标
B26: 项目增量财务内部收益率（%）（所得税前） | E26: =IRR(C17:AC17) -> 0.12456638
B27: 项目增量财务内部收益率（%）（所得税后） | E27: =IRR(C21:AC21) -> 0.11599219
B28: ="税前财务净现值(折现率 "&WACC*100&"%)" -> 税前财务净现值(折现率 6.825%) | E28: =NPV(DiscountRate,C17:AC17) -> 133147.11
B29: ="税后财务净现值(折现率 "&WACC*100&"%)" -> 税后财务净现值(折现率 6.825%) | E29: =NPV(DiscountRate,C21:AC21) -> 107966.84
B30: 增量投资回收期（年）（所得税前） | E30: {=(MATCH(1,IF(C18:AC18>0,1,0),0)-1)-INDEX($C$17:$AC$18,2,(MATCH(1,IF(C18:AC18>0,1,0),0)-1))/INDEX($C$17:$AC$18,1,(MATCH(1,IF(C18:AC18>0,1,0),0)))} -> 8.4481115
B31: 增量投资回收期（年）（所得税后） | E31: {=(MATCH(1,IF(C22:AC22>0,1,0),0)-1)-INDEX($C$21:$AC$22,2,(MATCH(1,IF(C22:AC22>0,1,0),0)-1))/INDEX($C$21:$AC$22,1,(MATCH(1,IF(C22:AC22>0,1,0),0)))} -> 8.6708866

Sheet 资本金现金流
A2: 资本金现金流量表
W3: 单位:万元
A4: 序 | B4: 年份 名称 | C4: 建设营运期
A5: 号 | C5: 1 | D5: 2 | E5: 3 | F5: 4 | G5: 5 | H5: 6 | I5: 7 | J5: 8 | K5: 9 | L5: 10 | M5: 11 | N5: 12 | O5: 13 | P5: 14 | Q5: 15 | R5: 16 | S5: 17 | T5: 18 | U5: 19 | V5: 20 | W5: 21 | X5: 22 | Y5: 23 | Z5: 24 | AA5: 25 | AB5: 26 | AC5: 27
A6: 1 | B6: “增量”现金流入 | C6: =SUM(C7:C10) -> 0 | D6: =SUM(D7:D10) -> 39737.25 | E6: =SUM(E7:E10) -> 39339.878 | F6: =SUM(F7:F10) -> 39180.929 | G6: =SUM(G7:G10) -> 39021.98 | H6: =SUM(H7:H10) -> 38863.031 | I6: =SUM(I7:I10) -> 38704.082 | J6: =SUM(J7:J10) -> 38545.132 | ... AC6: =SUM(AC7:AC10) -> 0
A7: 1.1 | B7: 营业收入 | C7: =损益表!D6 -> 0 | D7: =销售收入!E6 -> 39737.25 | E7: =销售收入!F6 -> 39339.878 | F7: =销售收入!G6 -> 39180.929 | G7: =销售收入!H6 -> 39021.98 | H7: =销售收入!I6 -> 38863.031 | I7: =销售收入!J6 -> 38704.082 | J7: =销售收入!K6 -> 38545.132 | K7: =销售收入!L6 -> 38386.183 | ... AC7: =销售收入!AD6 -> 0
A8: 1.2 | B8: 增值税初始收入 | D8: =销售收入!E40 -> 0 | E8: =销售收入!F40 -> 0 | F8: =销售收入!G40 -> 0 | G8: =销售收入!H40 -> 0 | H8: =销售收入!I40 -> 0 | I8: =销售收入!J40 -> 0 | J8: =销售收入!K40 -> 0 | K8: =销售收入!L40 -> 0 | ... AC8: =销售收入!AD40 -> 0
A9: 1.3 | B9: 回收固定资产余值 | G9: =F9 -> 0 | H9: =G9 -> 0 | I9: =H9 -> 0 | J9: =I9 -> 0 | K9: =J9 -> 0 | L9: =K9 -> 0 | M9: =L9 -> 0 | N9: =M9 -> 0 | ... Q9: =P9 -> 0 | S9: =R9 -> 0 | U9: =T9 -> 0
A10: 1.4 | B10: 回收流动资金
A11: 2 | B11: “增量”现金流出 | C11: =SUM(C12:C17) -> 81434.207 | D11: =SUM(D12:D18) -> 23522.202 | E11: =SUM(E12:E18) -> 23075.284 | F11: =SUM(F12:F18) -> 22642.554 | G11: =SUM(G12:G18) -> 22209.826 | H11: =SUM(H12:H18) -> 21777.1 | I11: =SUM(I12:I18) -> 21597.501 | J11: =SUM(J12:J18) -> 21164.779 | K11: =SUM(K12:K18) -> 20732.059 | ... AC11: =SUM(AC12:AC18) -> 147.55419
A12: 2.1 | B12: 项目资本金 | C12: =资金筹措!C12 -> 81434.207 | D12: =资金筹措!D12 -> 0 | E12: =资金筹措!E12 -> 0
A13: 2.4 | B13: 借款本金偿还 | D13: =还本付息!E16 -> 12434.21 | E13: =还本付息!F16 -> 12434.21 | F13: =还本付息!G16 -> 12434.21 | G13: =还本付息!H16 -> 12434.21 | H13: =还本付息!I16 -> 12434.21 | I13: =还本付息!J16 -> 12434.21 | J13: =还本付息!K16 -> 12434.21 | K13: =还本付息!L16 -> 12434.21 | ... AC13: =还本付息!AD16 -> 0
A14: 2.5 | B14: 借款利息支付 | D14: =还本付息!E17 -> 6714.4734 | E14: =还本付息!F17 -> 6266.8418 | F14: =还本付息!G17 -> 5819.2103 | G14: =还本付息!H17 -> 5371.5787 | H14: =还本付息!I17 -> 4923.9472 | I14: =还本付息!J17 -> 4476.3156 | J14: =还本付息!K17 -> 4028.684 | K14: =还本付息!L17 -> 3581.0525 | ... AC14: =还本付息!AD17 -> -1.7025741e-12
A15: 2.6 | B15: 经营成本 | C15: =总成本!D17 -> 0 | D15: =总成本!E17 -> 3001.1851 | E15: =总成本!F17 -> 3003.2646 | F15: =总成本!G17 -> 3005.3463 | G15: =总成本!H17 -> 3007.43 | H15: =总成本!I17 -> 3009.5159 | I15: =总成本!J17 -> 3278.0511 | J15: =总成本!K17 -> 3280.1411 | ... AC15: =总成本!AD17 -> 155.3202
A16: 2.7 | B16: 营业税金及附加 | C16: =损益表!D8 -> 0 | D16: =损益表!E8 -> 397.3725 | E16: =损益表!F8 -> 393.39878 | F16: =损益表!G8 -> 391.80928 | G16: =损益表!H8 -> 390.21979 | H16: =损益表!I8 -> 388.63031 | I16: =损益表!J8 -> 387.04082 | J16: =损益表!K8 -> 385.45132 | ... AC16: =损益表!AD8 -> 0
A17: 2.8 | B17: 所得税 | C17: =损益表!D13 -> 0 | D17: =损益表!E13 -> 0 | E17: =损益表!F13 -> 0 | F17: =损益表!G13 -> 0 | G17: =损益表!H13 -> 0 | H17: =损益表!I13 -> 0 | I17: =损益表!J13 -> 0 | J17: =损益表!K13 -> 0 | ... AC17: =损益表!AD13 -> 0
A18: 2.9 | B18: 反税基侵蚀补税/预扣税 | D18: =损益表!E19 -> 974.96097 | E18: =损益表!F19 -> 977.56863 | F18: =损益表!G19 -> 991.97815 | G18: =损益表!H19 -> 1006.3876 | H18: =损益表!I19 -> 1020.7969 | I18: =损益表!J19 -> 1021.8837 | J18: =损益表!K19 -> 1036.2928 | K18: =损益表!L19 -> 1050.7018 | ... AC18: =损益表!AD19 -> -7.76601
A19: 3 | B19: 净现金流量（所得税前） | C19: =C6-C11 -> -81434.207 | D19: =D21+D17+D18 -> 17190.009 | E19: =E21+E17+E18 -> 17242.162 | F19: =F21+F17+F18 -> 17530.353 | G19: =G21+G17+G18 -> 17818.541 | H19: =H21+H17+H18 -> 18106.727 | I19: =I21+I17+I18 -> 18128.464 | J19: =J21+J17+J18 -> 18416.646 | K19: =K21+K17+K18 -> 18704.826 | ... AC19: =AC21+AC17+AC18 -> -155.3202
A20: 4 | B20: 累计净现金流量（所得税前） | C20: =C19 -> -81434.207 | D20: =IF(D19=0,0,D19+C20) -> -64244.198 | E20: =IF(E19=0,0,E19+D20) -> -47002.036 | F20: =IF(F19=0,0,F19+E20) -> -29471.683 | G20: =IF(G19=0,0,G19+F20) -> -11653.142 | H20: =IF(H19=0,0,H19+G20) -> 6453.5849 | I20: =IF(I19=0,0,I19+H20) -> 24582.049 | J20: =IF(J19=0,0,J19+I20) -> 42998.695 | K20: =IF(K19=0,0,K19+J20) -> 61703.521 | ... AC20: =IF(AC19=0,0,AC19+AB20) -> 519825
A21: 5 | B21: 净现金流量（所得税后） | C21: =C6-C11 -> -81434.207 | D21: =D6-D11 -> 16215.048 | E21: =E6-E11 -> 16264.594 | F21: =F6-F11 -> 16538.374 | G21: =G6-G11 -> 16812.153 | H21: =H6-H11 -> 17085.93 | I21: =I6-I11 -> 17106.58 | J21: =J6-J11 -> 17380.353 | ... AC21: =AC6-AC11 -> -147.55419
A22: 6 | B22: 累计净现金流量（所得税后） | C22: =C21 -> -81434.207 | D22: =IF(D21=0,0,D21+C22) -> -65219.159 | E22: =IF(E21=0,0,E21+D22) -> -48954.565 | F22: =IF(F21=0,0,F21+E22) -> -32416.191 | G22: =IF(G21=0,0,G21+F22) -> -15604.038 | H22: =IF(H21=0,0,H21+G22) -> 1481.8927 | I22: =IF(I21=0,0,I21+H22) -> 18588.473 | J22: =IF(J21=0,0,J21+I22) -> 35968.826 | K22: =IF(K21=0,0,K21+J22) -> 53622.95 | ... AC22: =IF(AC21=0,0,AC21+AB22) -> 452322.55
B24: 财务内部收益(%)（所得税前） | E24: =IRR(C19:AC19) -> 0.2262975
B25: ="财务净现值(折现率 "&WACC*100&"%)（所得税前）" -> 财务净现值(折现率 6.825%)（所得税前） | E25: =NPV(DiscountRate,C19:AC19) -> 161892.22
B26: 投资回收期（所得税前） | E26: {=(MATCH(1,IF(C20:AC20>0,1,0),0)-1)-INDEX($C$19:$AC$20,2,(MATCH(1,IF(C20:AC20>0,1,0),0)-1))/INDEX($C$19:$AC$20,1,(MATCH(1,IF(C20:AC20>0,1,0),0)))} -> 5.6435808
B27: 财务内部收益(%)（所得税后） | E27: =IRR(C21:AC21) -> 0.21052865
B28: ="财务净现值(折现率 "&WACC*100&"%)（所得税后）" -> 财务净现值(折现率 6.825%)（所得税后） | E28: =NPV(DiscountRate,C21:AC21) -> 138383.91
B29: 投资回收期（所得税后） | E29: {=(MATCH(1,IF(C22:AC22>0,1,0),0)-1)-INDEX($C$21:$AC$22,2,(MATCH(1,IF(C22:AC22>0,1,0),0)-1))/INDEX($C$21:$AC$22,1,(MATCH(1,IF(C22:AC22>0,1,0),0)))} -> 5.9132682

Sheet 资产负债表
C1: =C15-C6 -> 0
A2: 资 产 负 债 表
D3: =D15-D6 -> 0 | E3: =E15-E6 -> 0 | F3: =F15-F6 -> 0 | G3: =G15-G6 -> 0 | H3: =H15-H6 -> 0 | I3: =I15-I6 -> 0 | J3: =J15-J6 -> 0 | K3: =K15-K6 -> 0 | ... AC3: =AC15-AC6 -> -4.7293724e-11
A4: 序 | B4: 年份 名称 | C4: 建设经营期
A5: 号 | C5: 1 | D5: 2 | E5: 3 | F5: 4 | G5: 5 | H5: 6 | I5: 7 | J5: 8 | K5: 9 | L5: 10 | M5: 11 | N5: 12 | O5: 13 | P5: 14 | Q5: 15 | R5: 16 | S5: 17 | T5: 18 | U5: 19 | V5: 20 | W5: 21 | X5: 22 | Y5: 23 | Z5: 24 | AA5: 25 | AB5: 26 | AC5: 27
A6: 1 | B6: 资产 | C6: =SUM(C7,C10:C12) -> 267947.36 | D6: =SUM(D7,D10:D13) -> 274037.41 | E6: =SUM(E7,E10:E13) -> 280177 | F6: =SUM(F7,F10:F13) -> 286590.37 | G6: =SUM(G7,G10:G13) -> 293277.53 | H6: =SUM(H7,H10:H13) -> 300238.46 | I6: =SUM(I7,I10:I13) -> 307220.04 | J6: =SUM(J7,J10:J13) -> 314475.39 | K6: =SUM(K7,K10:K13) -> 322004.52 | ... AC6: =SUM(AC7,AC10:AC13) -> 0
A7: 1.1 | B7: 流动资产总额 | C7: =SUM(C8:C9) -> 1500 | D7: =SUM(D8:D9) -> 17715.048 | E7: =SUM(E8:E9) -> 33979.642 | F7: =SUM(F8:F9) -> 50518.016 | G7: =SUM(G8:G9) -> 67330.17 | H7: =SUM(H8:H9) -> 84416.1 | I7: =SUM(I8:I9) -> 101522.68 | J7: =SUM(J8:J9) -> 118903.03 | ... AC7: =SUM(AC8:AC9) -> 0
A8: 1.1.1 | B8: 流动资产 | C8: =资金筹措!C9 -> 1500 | D8: =IF(C5>ConstructPeriod+OperationPeriod,0,C8+资金筹措!D9) -> 1500 | E8: =IF(D5<ConstructPeriod+OperationPeriod,D8+资金筹措!E9,0) -> 1500 | F8: =IF(E5<ConstructPeriod+OperationPeriod,E8,0) -> 1500 | G8: =IF(F5<ConstructPeriod+OperationPeriod,F8,0) -> 1500 | H8: =IF(G5<ConstructPeriod+OperationPeriod,G8,0) -> 1500 | I8: =IF(H5<ConstructPeriod+OperationPeriod,H8,0) -> 1500 | J8: =IF(I5<ConstructPeriod+OperationPeriod,I8,0) -> 1500 | K8: =IF(J5<ConstructPeriod+OperationPeriod,J8,0) -> 1500 | L8: =IF(K5<ConstructPeriod+OperationPeriod,K8,0) -> 1500 | M8: =IF(L5<ConstructPeriod+OperationPeriod,L8,0) -> 1500 | ... AC8: =IF(AB5<ConstructPeriod+OperationPeriod,AB8,0) -> 0
A9: 1.1.2 | B9: 累计盈余资金 | C9: =财务计划!C43 -> 0 | D9: =财务计划!D43 -> 16215.048 | E9: =财务计划!E43 -> 32479.642 | F9: =财务计划!F43 -> 49018.016 | G9: =财务计划!G43 -> 65830.17 | H9: =财务计划!H43 -> 82916.1 | I9: =财务计划!I43 -> 100022.68 | J9: =财务计划!J43 -> 117403.03 | ... AC9: =财务计划!AC43 -> 0
A10: 1.2 | B10: 在建工程 | C10: =FixedAssets -> 266447.36 | D10: =IF(D5<=ConstructPeriod,资金筹措!D7+资金筹措!D9+C10,0) -> 0
A11: 1.3 | B11: 固定资产净值 | C11: =折旧!G19 -> 0 | D11: =折旧!H19 -> 256322.36 | E11: =折旧!I19 -> 246197.36 | F11: =折旧!J19 -> 236072.36 | G11: =折旧!K19 -> 225947.36 | H11: =折旧!L19 -> 215822.36 | I11: =折旧!M19 -> 205697.36 | J11: =折旧!N19 -> 195572.36 | ... AC11: =折旧!AG19 -> 0
A12: 1.4 | B12: 无形及递延资产净值 | C12: =摊销!E20 -> 0 | D12: =摊销!F20 -> 0 | E12: =摊销!G20 -> 0 | F12: =摊销!H20 -> 0 | G12: =摊销!I20 -> 0 | H12: =摊销!J20 -> 0 | I12: =摊销!K20 -> 0 | J12: =摊销!L20 -> 0 | ... AC12: =摊销!AE20 -> 0
A13: 1.5 | B13: 可抵扣增值税形成资产 | C13: =销售收入!D38 -> 0 | D13: =销售收入!E41-SUM(销售收入!$E$42:销售收入!E42) -> 0 | E13: =销售收入!F41-SUM(销售收入!$E$42:销售收入!F42) -> 0 | F13: =销售收入!G41-SUM(销售收入!$E$42:销售收入!G42) -> 0 | G13: =销售收入!H41-SUM(销售收入!$E$42:销售收入!H42) -> 0 | H13: =销售收入!I41-SUM(销售收入!$E$42:销售收入!I42) -> 0 | I13: =销售收入!J41-SUM(销售收入!$E$42:销售收入!J42) -> 0 | J13: =销售收入!K41-SUM(销售收入!$E$42:销售收入!K42) -> 0 | K13: =销售收入!L41-SUM(销售收入!$E$42:销售收入!L42) -> 0 | ... AC13: =销售收入!AD41-SUM(销售收入!$E$42:销售收入!AD42) -> 0
